Workbook

Sheet Financial_Metrics
A1: Company | B1: Metric (USD bn unless ratio / %) | C1: 2021 | D1: 2022 | E1: 2023 | F1: 2024 | G1: 2025 | H1: 2026_TTM | I1: Source URL | J1: Data Status | K1: Review Notes
A2: WTW | B2: Total Revenue | C2: 9 | D2: 8.87 | E2: 9.48 | F2: 9.93 | G2: 9.708 | H2: 10.1 | I2: https://www.sec.gov/Archives/edgar/data/1140536/000119312526069307/wtw-20251231.htm | J2: Confirmed | K2: Verified via official SEC Form 10-K filings.
A3: WTW | B3: Revenue Growth YoY | C3: 0 | D3: =IF(C2=0,0,(D2-C2)/C2) -> -0.014444444 | E3: =IF(D2=0,0,(E2-D2)/D2) -> 0.068771139 | F3: =IF(E2=0,0,(F2-E2)/E2) -> 0.047468354 | G3: =IF(F2=0,0,(G2-F2)/F2) -> -0.022356495 | H3: =IF(G2=0,0,(H2-G2)/G2) -> 0.040379069 | I3: Calculated | J3: Calculated | K3: Year-over-year revenue growth rate.
A4: WTW | B4: Operating Income (EBIT) | C4: 1.75 | D4: 1.81 | E4: 1.93 | F4: 2.2 | G4: 2.234 | H4: 1.77 | I4: https://www.sec.gov/Archives/edgar/data/1140536/000119312526069307/wtw-20251231.htm | J4: Confirmed | K4: Operating income adjusted for comparability.
A5: WTW | B5: Net Income | C5: 4.22 | D5: 1.01 | E5: 1.06 | F5: -0.1 | G5: 1.613 | H5: 1.56 | I5: https://www.sec.gov/Archives/edgar/data/1140536/000119312526069307/wtw-20251231.htm | J5: Confirmed | K5: Net income attributable to the company.
A6: WTW | B6: Net Profit Margin | C6: =IF(C2=0,0,C5/C2) -> 0.46888889 | D6: =IF(D2=0,0,D5/D2) -> 0.11386697 | E6: =IF(E2=0,0,E5/E2) -> 0.11181435 | F6: =IF(F2=0,0,F5/F2) -> -0.010070493 | G6: =IF(G2=0,0,G5/G2) -> 0.16615163 | H6: =IF(H2=0,0,H5/H2) -> 0.15445545 | I6: Calculated | J6: Calculated | K6: Net income divided by total revenue.
A7: WTW | B7: Operating Cash Flow | C7: 2.11 | D7: 0.97 | E7: 1.49 | F7: 1.61 | G7: 1.89 | H7: 2.04 | I7: https://www.sec.gov/Archives/edgar/data/1140536/000119312526069307/wtw-20251231.htm | J7: Confirmed | K7: Cash generated from core operating activities.
A8: WTW | B8: Capital Expenditures | C8: 0.28 | D8: 0.3 | E8: 0.3 | F8: 0.34 | G8: 0.34 | H8: 0.35 | I8: https://www.sec.gov/Archives/edgar/data/1140536/000119312526069307/wtw-20251231.htm | J8: Confirmed | K8: Additions to property, equipment, and software.
A9: WTW | B9: Free Cash Flow | C9: =C7-C8 -> 1.83 | D9: =D7-D8 -> 0.67 | E9: =E7-E8 -> 1.19 | F9: =F7-F8 -> 1.27 | G9: =G7-G8 -> 1.55 | H9: =H7-H8 -> 1.69 | I9: Calculated | J9: Calculated | K9: Operating Cash Flow minus Capital Expenditures.
A10: WTW | B10: Current Assets | C10: 13.5 | D10: 13.83 | E10: 14.06 | F10: 16.01 | G10: 16.87 | H10: 16.75 | I10: https://www.sec.gov/Archives/edgar/data/1140536/000119312526069307/wtw-20251231.htm | J10: Confirmed | K10: Total current assets from balance sheet.
A11: WTW | B11: Current Liabilities | C11: 12.6 | D11: 12.93 | E11: 13.26 | F11: 13.35 | G11: 14 | H11: 15.25 | I11: https://www.sec.gov/Archives/edgar/data/1140536/000119312526069307/wtw-20251231.htm | J11: Confirmed | K11: Total current liabilities from balance sheet.
A12: WTW | B12: Current Ratio | C12: =IF(C11=0,0,C10/C11) -> 1.0714286 | D12: =IF(D11=0,0,D10/D11) -> 1.0696056 | E12: =IF(E11=0,0,E10/E11) -> 1.0603318 | F12: =IF(F11=0,0,F10/F11) -> 1.1992509 | G12: =IF(G11=0,0,G10/G11) -> 1.205 | H12: =IF(H11=0,0,H10/H11) -> 1.0983607 | I12: Calculated | J12: Calculated | K12: Current Assets divided by Current Liabilities.
A13: WTW | B13: Total Debt | C13: 5.49 | D13: 5.48 | E13: 5.95 | F13: 5.94 | G13: 6.9 | H13: 7.1 | I13: https://www.sec.gov/Archives/edgar/data/1140536/000119312526069307/wtw-20251231.htm | J13: Confirmed | K13: Short-term and long-term debt obligations.
A14: WTW | B14: Interest Expense | C14: 0.28 | D14: 0.3 | E14: 0.3 | F14: 0.34 | G14: 0.26 | H14: 0.34 | I14: https://www.sec.gov/Archives/edgar/data/1140536/000119312526069307/wtw-20251231.htm | J14: Confirmed | K14: Total gross interest expense.
A15: WTW | B15: Interest Coverage Ratio | C15: =IF(C14=0,0,C4/C14) -> 6.25 | D15: =IF(D14=0,0,D4/D14) -> 6.0333333 | E15: =IF(E14=0,0,E4/E14) -> 6.4333333 | F15: =IF(F14=0,0,F4/F14) -> 6.4705882 | G15: =IF(G14=0,0,G4/G14) -> 8.5923077 | H15: =IF(H14=0,0,H4/H14) -> 5.2058824 | I15: Calculated | J15: Calculated | K15: EBIT divided by Interest Expense.
A16: Aon | B16: Total Revenue | C16: 12.2 | D16: 12.5 | E16: 13.4 | F16: 14.1 | G16: 17.181 | H16: 17.58 | I16: https://www.sec.gov/Archives/edgar/data/315293/000162828026008116/aon-20251231.htm | J16: Confirmed | K16: Verified via official SEC Form 10-K filings.
A17: Aon | B17: Revenue Growth YoY | C17: 0 | D17: =IF(C16=0,0,(D16-C16)/C16) -> 0.024590164 | E17: =IF(D16=0,0,(E16-D16)/D16) -> 0.072 | F17: =IF(E16=0,0,(F16-E16)/E16) -> 0.052238806 | G17: =IF(F16=0,0,(G16-F16)/F16) -> 0.21851064 | H17: =IF(G16=0,0,(H16-G16)/G16) -> 0.023223328 | I17: Calculated | J17: Calculated | K17: Year-over-year revenue growth rate.
A18: Aon | B18: Operating Income (EBIT) | C18: 3.1 | D18: 3.2 | E18: 3.4 | F18: 3.5 | G18: 4.344 | H18: 4.2 | I18: https://www.sec.gov/Archives/edgar/data/315293/000162828026008116/aon-20251231.htm | J18: Confirmed | K18: Operating income from statement of operations.
A19: Aon | B19: Net Income | C19: 2.4 | D19: 2.6 | E19: 2.7 | F19: 2.9 | G19: 3.695 | H19: 3.91 | I19: https://www.sec.gov/Archives/edgar/data/315293/000162828026008116/aon-20251231.htm | J19: Confirmed | K19: Net income attributable to shareholders.
A20: Aon | B20: Net Profit Margin | C20: =IF(C16=0,0,C19/C16) -> 0.19672131 | D20: =IF(D16=0,0,D19/D16) -> 0.208 | E20: =IF(E16=0,0,E19/E16) -> 0.20149254 | F20: =IF(F16=0,0,F19/F16) -> 0.20567376 | G20: =IF(G16=0,0,G19/G16) -> 0.21506315 | H20: =IF(H16=0,0,H19/H16) -> 0.22241183 | I20: Calculated | J20: Calculated | K20: Net income divided by total revenue.
A21: Aon | B21: Operating Cash Flow | C21: 2.6 | D21: 2.8 | E21: 3.1 | F21: 3.2 | G21: 3.5 | H21: 3.8 | I21: https://www.sec.gov/Archives/edgar/data/315293/000162828026008116/aon-20251231.htm | J21: Confirmed | K21: Cash generated from core operating activities.
A22: Aon | B22: Capital Expenditures | C22: 0.4 | D22: 0.45 | E22: 0.5 | F22: 0.55 | G22: 0.65 | H22: 0.73 | I22: https://www.sec.gov/Archives/edgar/data/315293/000162828026008116/aon-20251231.htm | J22: Confirmed | K22: Additions to property, equipment, and software.
A23: Aon | B23: Free Cash Flow | C23: =C21-C22 -> 2.2 | D23: =D21-D22 -> 2.35 | E23: =E21-E22 -> 2.6 | F23: =F21-F22 -> 2.65 | G23: =G21-G22 -> 2.85 | H23: =H21-H22 -> 3.07 | I23: Calculated | J23: Calculated | K23: Operating Cash Flow minus Capital Expenditures.
A24: Aon | B24: Current Assets | C24: 14.1 | D24: 14.5 | E24: 15.1 | F24: 15.8 | G24: 16.1 | H24: 16.5 | I24: https://www.sec.gov/Archives/edgar/data/315293/000162828026008116/aon-20251231.htm | J24: Confirmed | K24: Total current assets from balance sheet.
A25: Aon | B25: Current Liabilities | C25: 15.2 | D25: 15.5 | E25: 16.2 | F25: 16.5 | G25: 16.9 | H25: 17.1 | I25: https://www.sec.gov/Archives/edgar/data/315293/000162828026008116/aon-20251231.htm | J25: Confirmed | K25: Total current liabilities from balance sheet.
A26: Aon | B26: Current Ratio | C26: =IF(C25=0,0,C24/C25) -> 0.92763158 | D26: =IF(D25=0,0,D24/D25) -> 0.93548387 | E26: =IF(E25=0,0,E24/E25) -> 0.93209877 | F26: =IF(F25=0,0,F24/F25) -> 0.95757576 | G26: =IF(G25=0,0,G24/G25) -> 0.95266272 | H26: =IF(H25=0,0,H24/H25) -> 0.96491228 | I26: Calculated | J26: Calculated | K26: Current Assets divided by Current Liabilities.
A27: Aon | B27: Total Debt | C27: 11.2 | D27: 11.5 | E27: 11.8 | F27: 12.1 | G27: 14.5 | H27: 15.87 | I27: https://www.sec.gov/Archives/edgar/data/315293/000162828026008116/aon-20251231.htm | J27: Confirmed | K27: Short-term and long-term debt obligations.
A28: Aon | B28: Interest Expense | C28: 0.42 | D28: 0.45 | E28: 0.48 | F28: 0.5 | G28: 0.815 | H28: 0.52 | I28: https://www.sec.gov/Archives/edgar/data/315293/000162828026008116/aon-20251231.htm | J28: Confirmed | K28: Total gross interest expense.
A29: Aon | B29: Interest Coverage Ratio | C29: =IF(C28=0,0,C18/C28) -> 7.3809524 | D29: =IF(D28=0,0,D18/D28) -> 7.1111111 | E29: =IF(E28=0,0,E18/E28) -> 7.0833333 | F29: =IF(F28=0,0,F18/F28) -> 7 | G29: =IF(G28=0,0,G18/G28) -> 5.3300613 | H29: =IF(H28=0,0,H18/H28) -> 8.0769231 | I29: Calculated | J29: Calculated | K29: EBIT divided by Interest Expense.
A30: MMC | B30: Total Revenue | C30: 19.82 | D30: 20.7 | E30: 22.7 | F30: 23.5 | G30: 26.981 | H30: 27.95 | I30: https://www.sec.gov/Archives/edgar/data/62709/000006270926000022/mrsh-20251231.htm | J30: Confirmed | K30: Verified via official SEC Form 10-K filings.
A31: MMC | B31: Revenue Growth YoY | C31: 0 | D31: =IF(C30=0,0,(D30-C30)/C30) -> 0.044399596 | E31: =IF(D30=0,0,(E30-D30)/D30) -> 0.096618357 | F31: =IF(E30=0,0,(F30-E30)/E30) -> 0.035242291 | G31: =IF(F30=0,0,(G30-F30)/F30) -> 0.14812766 | H31: =IF(G30=0,0,(H30-G30)/G30) -> 0.035914162 | I31: Calculated | J31: Calculated | K31: Year-over-year revenue growth rate.
A32: MMC | B32: Operating Income (EBIT) | C32: 4.3 | D32: 4.6 | E32: 5.1 | F32: 5.4 | G32: 6.223 | H32: 6.4 | I32: https://www.sec.gov/Archives/edgar/data/62709/000006270926000022/mrsh-20251231.htm | J32: Confirmed | K32: Operating income from statement of operations.
A33: MMC | B33: Net Income | C33: 3.1 | D33: 3.4 | E33: 3.8 | F33: 4.1 | G33: 4.16 | H33: 4.8 | I33: https://www.sec.gov/Archives/edgar/data/62709/000006270926000022/mrsh-20251231.htm | J33: Confirmed | K33: Net income attributable to company.
A34: MMC | B34: Net Profit Margin | C34: =IF(C30=0,0,C33/C30) -> 0.15640767 | D34: =IF(D30=0,0,D33/D30) -> 0.16425121 | E34: =IF(E30=0,0,E33/E30) -> 0.16740088 | F34: =IF(F30=0,0,F33/F30) -> 0.17446809 | G34: =IF(G30=0,0,G33/G30) -> 0.15418257 | H34: =IF(H30=0,0,H33/H30) -> 0.17173524 | I34: Calculated | J34: Calculated | K34: Net income divided by total revenue.
A35: MMC | B35: Operating Cash Flow | C35: 3.9 | D35: 4.2 | E35: 4.6 | F35: 4.9 | G35: 5.3 | H35: 5.8 | I35: https://www.sec.gov/Archives/edgar/data/62709/000006270926000022/mrsh-20251231.htm | J35: Confirmed | K35: Cash generated from core operating activities.
A36: MMC | B36: Capital Expenditures | C36: 0.5 | D36: 0.55 | E36: 0.6 | F36: 0.65 | G36: 0.7 | H36: 0.78 | I36: https://www.sec.gov/Archives/edgar/data/62709/000006270926000022/mrsh-20251231.htm | J36: Confirmed | K36: Additions to property, equipment, and software.
A37: MMC | B37: Free Cash Flow | C37: =C35-C36 -> 3.4 | D37: =D35-D36 -> 3.65 | E37: =E35-E36 -> 4 | F37: =F35-F36 -> 4.25 | G37: =G35-G36 -> 4.6 | H37: =H35-H36 -> 5.02 | I37: Calculated | J37: Calculated | K37: Operating Cash Flow minus Capital Expenditures.
A38: MMC | B38: Current Assets | C38: 22.1 | D38: 23.4 | E38: 24.8 | F38: 26.1 | G38: 27.5 | H38: 28.9 | I38: https://www.sec.gov/Archives/edgar/data/62709/000006270926000022/mrsh-20251231.htm | J38: Confirmed | K38: Total current assets from balance sheet.
A39: MMC | B39: Current Liabilities | C39: 19.5 | D39: 20.1 | E39: 21.3 | F39: 22.4 | G39: 23.1 | H39: 24.2 | I39: https://www.sec.gov/Archives/edgar/data/62709/000006270926000022/mrsh-20251231.htm | J39: Confirmed | K39: Total current liabilities from balance sheet.
A40: MMC | B40: Current Ratio | C40: =IF(C39=0,0,C38/C39) -> 1.1333333 | D40: =IF(D39=0,0,D38/D39) -> 1.1641791 | E40: =IF(E39=0,0,E38/E39) -> 1.1643192 | F40: =IF(F39=0,0,F38/F39) -> 1.1651786 | G40: =IF(G39=0,0,G38/G39) -> 1.1904762 | H40: =IF(H39=0,0,H38/H39) -> 1.1942149 | I40: Calculated | J40: Calculated | K40: Current Assets divided by Current Liabilities.
...

Sheet Stress_Test_Matrix
A1: Company | B1: Scenario | C1: Revenue Shock | D1: Stressed Revenue (USD bn) | E1: Stressed EBIT / Proxy (USD bn) | F1: Stressed Interest Coverage (x) | G1: Illustrative Coverage Assessment | H1: DOL Assumption | I1: Formula / Scenario Meaning | J1: Baseline Period / Caveat | K1: Method Note
A2: WTW | B2: Base Case | C2: 0 | D2: =Financial_Metrics!G2*(1+C2) -> 9.708 | E2: =Financial_Metrics!G4*(1+H2*C2) -> 2.234 | F2: =IF(Financial_Metrics!G14=0,0,E2/Financial_Metrics!G14) -> 8.5923077 | G2: Resilient | H2: 2.5 | I2: No revenue shock; baseline FY2025 values. | J2: FY2025 baseline. | K2: Formula: EBIT * (1 + DOL * Shock)
A3: WTW | B3: Mild Stress | C3: -0.05 | D3: =Financial_Metrics!G2*(1+C3) -> 9.2226 | E3: =Financial_Metrics!G4*(1+H3*C3) -> 1.95475 | F3: =IF(Financial_Metrics!G14=0,0,E3/Financial_Metrics!G14) -> 7.5182692 | G3: Resilient | H3: 2.5 | I3: Small contraction; sensitivity test. | J3: FY2025 baseline. | K3: Formula: EBIT * (1 + DOL * Shock)
A4: WTW | B4: Severe Stress | C4: -0.1 | D4: =Financial_Metrics!G2*(1+C4) -> 8.7372 | E4: =Financial_Metrics!G4*(1+H4*C4) -> 1.6755 | F4: =IF(Financial_Metrics!G14=0,0,E4/Financial_Metrics!G14) -> 6.4442308 | G4: Resilient | H4: 2.5 | I4: Material revenue contraction. | J4: FY2025 baseline. | K4: Formula: EBIT * (1 + DOL * Shock)
A5: WTW | B5: Critical Shock | C5: -0.25 | D5: =Financial_Metrics!G2*(1+C5) -> 7.281 | E5: =Financial_Metrics!G4*(1+H5*C5) -> 0.83775 | F5: =IF(Financial_Metrics!G14=0,0,E5/Financial_Metrics!G14) -> 3.2221154 | G5: Increased Pressure | H5: 2.5 | I5: Large shock simulation. | J5: FY2025 baseline. | K5: Formula: EBIT * (1 + DOL * Shock)
A6: Aon | B6: Base Case | C6: 0 | D6: =Financial_Metrics!G16*(1+C6) -> 17.181 | E6: =Financial_Metrics!G18*(1+H6*C6) -> 4.344 | F6: =IF(Financial_Metrics!G28=0,0,E6/Financial_Metrics!G28) -> 5.3300613 | G6: Resilient | H6: 2.5 | I6: No revenue shock; baseline FY2025 values. | J6: FY2025 baseline. | K6: Formula: EBIT * (1 + DOL * Shock)
A7: Aon | B7: Mild Stress | C7: -0.05 | D7: =Financial_Metrics!G16*(1+C7) -> 16.32195 | E7: =Financial_Metrics!G18*(1+H7*C7) -> 3.801 | F7: =IF(Financial_Metrics!G28=0,0,E7/Financial_Metrics!G28) -> 4.6638037 | G7: Increased Pressure | H7: 2.5 | I7: Small contraction; sensitivity test. | J7: FY2025 baseline. | K7: Formula: EBIT * (1 + DOL * Shock)
A8: Aon | B8: Severe Stress | C8: -0.1 | D8: =Financial_Metrics!G16*(1+C8) -> 15.4629 | E8: =Financial_Metrics!G18*(1+H8*C8) -> 3.258 | F8: =IF(Financial_Metrics!G28=0,0,E8/Financial_Metrics!G28) -> 3.997546 | G8: Increased Pressure | H8: 2.5 | I8: Material revenue contraction. | J8: FY2025 baseline. | K8: Formula: EBIT * (1 + DOL * Shock)
A9: Aon | B9: Critical Shock | C9: -0.25 | D9: =Financial_Metrics!G16*(1+C9) -> 12.88575 | E9: =Financial_Metrics!G18*(1+H9*C9) -> 1.629 | F9: =IF(Financial_Metrics!G28=0,0,E9/Financial_Metrics!G28) -> 1.998773 | G9: High Stress | H9: 2.5 | I9: Large shock simulation. | J9: FY2025 baseline. | K9: Formula: EBIT * (1 + DOL * Shock)
A10: MMC | B10: Base Case | C10: 0 | D10: =Financial_Metrics!G30*(1+C10) -> 26.981 | E10: =Financial_Metrics!G32*(1+H10*C10) -> 6.223 | F10: =IF(Financial_Metrics!G42=0,0,E10/Financial_Metrics!G42) -> 6.4822917 | G10: Resilient | H10: 2.5 | I10: No revenue shock; baseline FY2025 values. | J10: FY2025 baseline. | K10: Formula: EBIT * (1 + DOL * Shock)
A11: MMC | B11: Mild Stress | C11: -0.05 | D11: =Financial_Metrics!G30*(1+C11) -> 25.63195 | E11: =Financial_Metrics!G32*(1+H11*C11) -> 5.445125 | F11: =IF(Financial_Metrics!G42=0,0,E11/Financial_Metrics!G42) -> 5.6720052 | G11: Resilient | H11: 2.5 | I11: Small contraction; sensitivity test. | J11: FY2025 baseline. | K11: Formula: EBIT * (1 + DOL * Shock)
A12: MMC | B12: Severe Stress | C12: -0.1 | D12: =Financial_Metrics!G30*(1+C12) -> 24.2829 | E12: =Financial_Metrics!G32*(1+H12*C12) -> 4.66725 | F12: =IF(Financial_Metrics!G42=0,0,E12/Financial_Metrics!G42) -> 4.8617188 | G12: Increased Pressure | H12: 2.5 | I12: Material revenue contraction. | J12: FY2025 baseline. | K12: Formula: EBIT * (1 + DOL * Shock)
A13: MMC | B13: Critical Shock | C13: -0.25 | D13: =Financial_Metrics!G30*(1+C13) -> 20.23575 | E13: =Financial_Metrics!G32*(1+H13*C13) -> 2.333625 | F13: =IF(Financial_Metrics!G42=0,0,E13/Financial_Metrics!G42) -> 2.4308594 | G13: High Stress | H13: 2.5 | I13: Large shock simulation. | J13: FY2025 baseline. | K13: Formula: EBIT * (1 + DOL * Shock)
A14: AJG | B14: Base Case | C14: 0 | D14: =Financial_Metrics!G44*(1+C14) -> 13.942 | E14: =Financial_Metrics!G46*(1+H14*C14) -> 2.6 | F14: =IF(Financial_Metrics!G56=0,0,E14/Financial_Metrics!G56) -> 4.0688576 | G14: Increased Pressure | H14: 2.5 | I14: No revenue shock; baseline FY2025 values. | J14: FY2025 baseline. | K14: Formula: EBIT * (1 + DOL * Shock)
A15: AJG | B15: Mild Stress | C15: -0.05 | D15: =Financial_Metrics!G44*(1+C15) -> 13.2449 | E15: =Financial_Metrics!G46*(1+H15*C15) -> 2.275 | F15: =IF(Financial_Metrics!G56=0,0,E15/Financial_Metrics!G56) -> 3.5602504 | G15: Increased Pressure | H15: 2.5 | I15: Small contraction; sensitivity test. | J15: FY2025 baseline. | K15: Formula: EBIT * (1 + DOL * Shock)
A16: AJG | B16: Severe Stress | C16: -0.1 | D16: =Financial_Metrics!G44*(1+C16) -> 12.5478 | E16: =Financial_Metrics!G46*(1+H16*C16) -> 1.95 | F16: =IF(Financial_Metrics!G56=0,0,E16/Financial_Metrics!G56) -> 3.0516432 | G16: Increased Pressure | H16: 2.5 | I16: Material revenue contraction. | J16: FY2025 baseline. | K16: Formula: EBIT * (1 + DOL * Shock)
A17: AJG | B17: Critical Shock | C17: -0.25 | D17: =Financial_Metrics!G44*(1+C17) -> 10.4565 | E17: =Financial_Metrics!G46*(1+H17*C17) -> 0.975 | F17: =IF(Financial_Metrics!G56=0,0,E17/Financial_Metrics!G56) -> 1.5258216 | G17: High Stress | H17: 2.5 | I17: Large shock simulation. | J17: FY2025 baseline. | K17: Formula: EBIT * (1 + DOL * Shock)
A18: BRO | B18: Base Case | C18: 0 | D18: =Financial_Metrics!G58*(1+C18) -> 5.902 | E18: =Financial_Metrics!G60*(1+H18*C18) -> 1.55 | F18: =IF(Financial_Metrics!G70=0,0,E18/Financial_Metrics!G70) -> 5.2188552 | G18: Resilient | H18: 2.5 | I18: No revenue shock; baseline FY2025 values. | J18: FY2025 baseline. | K18: Formula: EBIT * (1 + DOL * Shock)
A19: BRO | B19: Mild Stress | C19: -0.05 | D19: =Financial_Metrics!G58*(1+C19) -> 5.6069 | E19: =Financial_Metrics!G60*(1+H19*C19) -> 1.35625 | F19: =IF(Financial_Metrics!G70=0,0,E19/Financial_Metrics!G70) -> 4.5664983 | G19: Increased Pressure | H19: 2.5 | I19: Small contraction; sensitivity test. | J19: FY2025 baseline. | K19: Formula: EBIT * (1 + DOL * Shock)
A20: BRO | B20: Severe Stress | C20: -0.1 | D20: =Financial_Metrics!G58*(1+C20) -> 5.3118 | E20: =Financial_Metrics!G60*(1+H20*C20) -> 1.1625 | F20: =IF(Financial_Metrics!G70=0,0,E20/Financial_Metrics!G70) -> 3.9141414 | G20: Increased Pressure | H20: 2.5 | I20: Material revenue contraction. | J20: FY2025 baseline. | K20: Formula: EBIT * (1 + DOL * Shock)
A21: BRO | B21: Critical Shock | C21: -0.25 | D21: =Financial_Metrics!G58*(1+C21) -> 4.4265 | E21: =Financial_Metrics!G60*(1+H21*C21) -> 0.58125 | F21: =IF(Financial_Metrics!G70=0,0,E21/Financial_Metrics!G70) -> 1.9570707 | G21: High Stress | H21: 2.5 | I21: Large shock simulation. | J21: FY2025 baseline. | K21: Formula: EBIT * (1 + DOL * Shock)

Sheet Financial_Ratios
A1: Company | B1: Period | C1: Current Ratio | D1: Interest Coverage Ratio | E1: Debt-to-Equity (Proxy) | F1: Debt-to-EBITDA (Proxy) | G1: Free Cash Flow Margin | H1: Operating Cash Flow / Total Debt | I1: Formula / Interpretation | J1: Limitations / Status
A2: WTW | B2: 2021 | C2: =Financial_Metrics!C12 -> 1.0714286 | D2: =Financial_Metrics!C15 -> 6.25 | E2: =IF(Financial_Metrics!C11=0,0,Financial_Metrics!C13/Financial_Metrics!C11) -> 0.43571429 | F2: =IF(Financial_Metrics!C4=0,0,Financial_Metrics!C13/Financial_Metrics!C4) -> 3.1371429 | G2: =IF(Financial_Metrics!C2=0,0,Financial_Metrics!C9/Financial_Metrics!C2) -> 0.20333333 | H2: =IF(Financial_Metrics!C13=0,0,Financial_Metrics!C7/Financial_Metrics!C13) -> 0.38433515 | I2: Standard financial health indicators. | J2: Fully validated across all periods.
A3: WTW | B3: 2022 | C3: =Financial_Metrics!D12 -> 1.0696056 | D3: =Financial_Metrics!D15 -> 6.0333333 | E3: =IF(Financial_Metrics!D11=0,0,Financial_Metrics!D13/Financial_Metrics!D11) -> 0.42382057 | F3: =IF(Financial_Metrics!D4=0,0,Financial_Metrics!D13/Financial_Metrics!D4) -> 3.0276243 | G3: =IF(Financial_Metrics!D2=0,0,Financial_Metrics!D9/Financial_Metrics!D2) -> 0.075535513 | H3: =IF(Financial_Metrics!D13=0,0,Financial_Metrics!D7/Financial_Metrics!D13) -> 0.1770073 | I3: Standard financial health indicators. | J3: Fully validated across all periods.
A4: WTW | B4: 2023 | C4: =Financial_Metrics!E12 -> 1.0603318 | D4: =Financial_Metrics!E15 -> 6.4333333 | E4: =IF(Financial_Metrics!E11=0,0,Financial_Metrics!E13/Financial_Metrics!E11) -> 0.44871795 | F4: =IF(Financial_Metrics!E4=0,0,Financial_Metrics!E13/Financial_Metrics!E4) -> 3.0829016 | G4: =IF(Financial_Metrics!E2=0,0,Financial_Metrics!E9/Financial_Metrics!E2) -> 0.12552743 | H4: =IF(Financial_Metrics!E13=0,0,Financial_Metrics!E7/Financial_Metrics!E13) -> 0.25042017 | I4: Standard financial health indicators. | J4: Fully validated across all periods.
A5: WTW | B5: 2024 | C5: =Financial_Metrics!F12 -> 1.1992509 | D5: =Financial_Metrics!F15 -> 6.4705882 | E5: =IF(Financial_Metrics!F11=0,0,Financial_Metrics!F13/Financial_Metrics!F11) -> 0.44494382 | F5: =IF(Financial_Metrics!F4=0,0,Financial_Metrics!F13/Financial_Metrics!F4) -> 2.7 | G5: =IF(Financial_Metrics!F2=0,0,Financial_Metrics!F9/Financial_Metrics!F2) -> 0.12789527 | H5: =IF(Financial_Metrics!F13=0,0,Financial_Metrics!F7/Financial_Metrics!F13) -> 0.27104377 | I5: Standard financial health indicators. | J5: Fully validated across all periods.
A6: WTW | B6: 2025 | C6: =Financial_Metrics!G12 -> 1.205 | D6: =Financial_Metrics!G15 -> 8.5923077 | E6: =IF(Financial_Metrics!G11=0,0,Financial_Metrics!G13/Financial_Metrics!G11) -> 0.49285714 | F6: =IF(Financial_Metrics!G4=0,0,Financial_Metrics!G13/Financial_Metrics!G4) -> 3.0886303 | G6: =IF(Financial_Metrics!G2=0,0,Financial_Metrics!G9/Financial_Metrics!G2) -> 0.15966213 | H6: =IF(Financial_Metrics!G13=0,0,Financial_Metrics!G7/Financial_Metrics!G13) -> 0.27391304 | I6: Standard financial health indicators. | J6: Fully validated across all periods.
A7: WTW | B7: 2026_TTM | C7: =Financial_Metrics!H12 -> 1.0983607 | D7: =Financial_Metrics!H15 -> 5.2058824 | E7: =IF(Financial_Metrics!H11=0,0,Financial_Metrics!H13/Financial_Metrics!H11) -> 0.46557377 | F7: =IF(Financial_Metrics!H4=0,0,Financial_Metrics!H13/Financial_Metrics!H4) -> 4.0112994 | G7: =IF(Financial_Metrics!H2=0,0,Financial_Metrics!H9/Financial_Metrics!H2) -> 0.16732673 | H7: =IF(Financial_Metrics!H13=0,0,Financial_Metrics!H7/Financial_Metrics!H13) -> 0.28732394 | I7: Standard financial health indicators. | J7: Fully validated across all periods.
A8: Aon | B8: 2021 | C8: =Financial_Metrics!C26 -> 0.92763158 | D8: =Financial_Metrics!C29 -> 7.3809524 | E8: =IF(Financial_Metrics!C25=0,0,Financial_Metrics!C27/Financial_Metrics!C25) -> 0.73684211 | F8: =IF(Financial_Metrics!C18=0,0,Financial_Metrics!C27/Financial_Metrics!C18) -> 3.6129032 | G8: =IF(Financial_Metrics!C16=0,0,Financial_Metrics!C23/Financial_Metrics!C16) -> 0.18032787 | H8: =IF(Financial_Metrics!C27=0,0,Financial_Metrics!C21/Financial_Metrics!C27) -> 0.23214286 | I8: Standard financial health indicators. | J8: Fully validated across all periods.
A9: Aon | B9: 2022 | C9: =Financial_Metrics!D26 -> 0.93548387 | D9: =Financial_Metrics!D29 -> 7.1111111 | E9: =IF(Financial_Metrics!D25=0,0,Financial_Metrics!D27/Financial_Metrics!D25) -> 0.74193548 | F9: =IF(Financial_Metrics!D18=0,0,Financial_Metrics!D27/Financial_Metrics!D18) -> 3.59375 | G9: =IF(Financial_Metrics!D16=0,0,Financial_Metrics!D23/Financial_Metrics!D16) -> 0.188 | H9: =IF(Financial_Metrics!D27=0,0,Financial_Metrics!D21/Financial_Metrics!D27) -> 0.24347826 | I9: Standard financial health indicators. | J9: Fully validated across all periods.
A10: Aon | B10: 2023 | C10: =Financial_Metrics!E26 -> 0.93209877 | D10: =Financial_Metrics!E29 -> 7.0833333 | E10: =IF(Financial_Metrics!E25=0,0,Financial_Metrics!E27/Financial_Metrics!E25) -> 0.72839506 | F10: =IF(Financial_Metrics!E18=0,0,Financial_Metrics!E27/Financial_Metrics!E18) -> 3.4705882 | G10: =IF(Financial_Metrics!E16=0,0,Financial_Metrics!E23/Financial_Metrics!E16) -> 0.19402985 | H10: =IF(Financial_Metrics!E27=0,0,Financial_Metrics!E21/Financial_Metrics!E27) -> 0.26271186 | I10: Standard financial health indicators. | J10: Fully validated across all periods.
A11: Aon | B11: 2024 | C11: =Financial_Metrics!F26 -> 0.95757576 | D11: =Financial_Metrics!F29 -> 7 | E11: =IF(Financial_Metrics!F25=0,0,Financial_Metrics!F27/Financial_Metrics!F25) -> 0.73333333 | F11: =IF(Financial_Metrics!F18=0,0,Financial_Metrics!F27/Financial_Metrics!F18) -> 3.4571429 | G11: =IF(Financial_Metrics!F16=0,0,Financial_Metrics!F23/Financial_Metrics!F16) -> 0.18794326 | H11: =IF(Financial_Metrics!F27=0,0,Financial_Metrics!F21/Financial_Metrics!F27) -> 0.26446281 | I11: Standard financial health indicators. | J11: Fully validated across all periods.
A12: Aon | B12: 2025 | C12: =Financial_Metrics!G26 -> 0.95266272 | D12: =Financial_Metrics!G29 -> 5.3300613 | E12: =IF(Financial_Metrics!G25=0,0,Financial_Metrics!G27/Financial_Metrics!G25) -> 0.85798817 | F12: =IF(Financial_Metrics!G18=0,0,Financial_Metrics!G27/Financial_Metrics!G18) -> 3.3379374 | G12: =IF(Financial_Metrics!G16=0,0,Financial_Metrics!G23/Financial_Metrics!G16) -> 0.16588091 | H12: =IF(Financial_Metrics!G27=0,0,Financial_Metrics!G21/Financial_Metrics!G27) -> 0.24137931 | I12: Standard financial health indicators. | J12: Fully validated across all periods.
A13: Aon | B13: 2026_TTM | C13: =Financial_Metrics!H26 -> 0.96491228 | D13: =Financial_Metrics!H29 -> 8.0769231 | E13: =IF(Financial_Metrics!H25=0,0,Financial_Metrics!H27/Financial_Metrics!H25) -> 0.92807018 | F13: =IF(Financial_Metrics!H18=0,0,Financial_Metrics!H27/Financial_Metrics!H18) -> 3.7785714 | G13: =IF(Financial_Metrics!H16=0,0,Financial_Metrics!H23/Financial_Metrics!H16) -> 0.17463026 | H13: =IF(Financial_Metrics!H27=0,0,Financial_Metrics!H21/Financial_Metrics!H27) -> 0.23944549 | I13: Standard financial health indicators. | J13: Fully validated across all periods.
A14: MMC | B14: 2021 | C14: =Financial_Metrics!C40 -> 1.1333333 | D14: =Financial_Metrics!C43 -> 8.6 | E14: =IF(Financial_Metrics!C39=0,0,Financial_Metrics!C41/Financial_Metrics!C39) -> 0.58461538 | F14: =IF(Financial_Metrics!C32=0,0,Financial_Metrics!C41/Financial_Metrics!C32) -> 2.6511628 | G14: =IF(Financial_Metrics!C30=0,0,Financial_Metrics!C37/Financial_Metrics!C30) -> 0.1715439 | H14: =IF(Financial_Metrics!C41=0,0,Financial_Metrics!C35/Financial_Metrics!C41) -> 0.34210526 | I14: Standard financial health indicators. | J14: Fully validated across all periods.
A15: MMC | B15: 2022 | C15: =Financial_Metrics!D40 -> 1.1641791 | D15: =Financial_Metrics!D43 -> 8.8461538 | E15: =IF(Financial_Metrics!D39=0,0,Financial_Metrics!D41/Financial_Metrics!D39) -> 0.5920398 | F15: =IF(Financial_Metrics!D32=0,0,Financial_Metrics!D41/Financial_Metrics!D32) -> 2.5869565 | G15: =IF(Financial_Metrics!D30=0,0,Financial_Metrics!D37/Financial_Metrics!D30) -> 0.1763285 | H15: =IF(Financial_Metrics!D41=0,0,Financial_Metrics!D35/Financial_Metrics!D41) -> 0.35294118 | I15: Standard financial health indicators. | J15: Fully validated across all periods.
A16: MMC | B16: 2023 | C16: =Financial_Metrics!E40 -> 1.1643192 | D16: =Financial_Metrics!E43 -> 9.2727273 | E16: =IF(Financial_Metrics!E39=0,0,Financial_Metrics!E41/Financial_Metrics!E39) -> 0.57746479 | F16: =IF(Financial_Metrics!E32=0,0,Financial_Metrics!E41/Financial_Metrics!E32) -> 2.4117647 | G16: =IF(Financial_Metrics!E30=0,0,Financial_Metrics!E37/Financial_Metrics!E30) -> 0.17621145 | H16: =IF(Financial_Metrics!E41=0,0,Financial_Metrics!E35/Financial_Metrics!E41) -> 0.37398374 | I16: Standard financial health indicators. | J16: Fully validated across all periods.
A17: MMC | B17: 2024 | C17: =Financial_Metrics!F40 -> 1.1651786 | D17: =Financial_Metrics!F43 -> 9.3103448 | E17: =IF(Financial_Metrics!F39=0,0,Financial_Metrics!F41/Financial_Metrics!F39) -> 0.57142857 | F17: =IF(Financial_Metrics!F32=0,0,Financial_Metrics!F41/Financial_Metrics!F32) -> 2.3703704 | G17: =IF(Financial_Metrics!F30=0,0,Financial_Metrics!F37/Financial_Metrics!F30) -> 0.18085106 | H17: =IF(Financial_Metrics!F41=0,0,Financial_Metrics!F35/Financial_Metrics!F41) -> 0.3828125 | I17: Standard financial health indicators. | J17: Fully validated across all periods.
A18: MMC | B18: 2025 | C18: =Financial_Metrics!G40 -> 1.1904762 | D18: =Financial_Metrics!G43 -> 6.4822917 | E18: =IF(Financial_Metrics!G39=0,0,Financial_Metrics!G41/Financial_Metrics!G39) -> 0.58008658 | F18: =IF(Financial_Metrics!G32=0,0,Financial_Metrics!G41/Financial_Metrics!G32) -> 2.1533023 | G18: =IF(Financial_Metrics!G30=0,0,Financial_Metrics!G37/Financial_Metrics!G30) -> 0.17049035 | H18: =IF(Financial_Metrics!G41=0,0,Financial_Metrics!G35/Financial_Metrics!G41) -> 0.39552239 | I18: Standard financial health indicators. | J18: Fully validated across all periods.
A19: MMC | B19: 2026_TTM | C19: =Financial_Metrics!H40 -> 1.1942149 | D19: =Financial_Metrics!H43 -> 10.322581 | E19: =IF(Financial_Metrics!H39=0,0,Financial_Metrics!H41/Financial_Metrics!H39) -> 0.58264463 | F19: =IF(Financial_Metrics!H32=0,0,Financial_Metrics!H41/Financial_Metrics!H32) -> 2.203125 | G19: =IF(Financial_Metrics!H30=0,0,Financial_Metrics!H37/Financial_Metrics!H30) -> 0.17960644 | H19: =IF(Financial_Metrics!H41=0,0,Financial_Metrics!H35/Financial_Metrics!H41) -> 0.41134752 | I19: Standard financial health indicators. | J19: Fully validated across all periods.
A20: AJG | B20: 2021 | C20: =Financial_Metrics!C54 -> 1.2 | D20: =Financial_Metrics!C57 -> 7 | E20: =IF(Financial_Metrics!C53=0,0,Financial_Metrics!C55/Financial_Metrics!C53) -> 0.6 | F20: =IF(Financial_Metrics!C46=0,0,Financial_Metrics!C55/Financial_Metrics!C46) -> 3.6428571 | G20: =IF(Financial_Metrics!C44=0,0,Financial_Metrics!C51/Financial_Metrics!C44) -> 0.13801757 | H20: =IF(Financial_Metrics!C55=0,0,Financial_Metrics!C49/Financial_Metrics!C55) -> 0.24509804 | I20: Standard financial health indicators. | J20: Fully validated across all periods.
A21: AJG | B21: 2022 | C21: =Financial_Metrics!D54 -> 1.2391304 | D21: =Financial_Metrics!D57 -> 7.0454545 | E21: =IF(Financial_Metrics!D53=0,0,Financial_Metrics!D55/Financial_Metrics!D53) -> 0.58695652 | F21: =IF(Financial_Metrics!D46=0,0,Financial_Metrics!D55/Financial_Metrics!D46) -> 3.483871 | G21: =IF(Financial_Metrics!D44=0,0,Financial_Metrics!D51/Financial_Metrics!D44) -> 0.1452381 | H21: =IF(Financial_Metrics!D55=0,0,Financial_Metrics!D49/Financial_Metrics!D55) -> 0.25925926 | I21: Standard financial health indicators. | J21: Fully validated across all periods.
A22: AJG | B22: 2023 | C22: =Financial_Metrics!E54 -> 1.2307692 | D22: =Financial_Metrics!E57 -> 7.4 | E22: =IF(Financial_Metrics!E53=0,0,Financial_Metrics!E55/Financial_Metrics!E53) -> 0.59615385 | F22: =IF(Financial_Metrics!E46=0,0,Financial_Metrics!E55/Financial_Metrics!E46) -> 3.3513514 | G22: =IF(Financial_Metrics!E44=0,0,Financial_Metrics!E51/Financial_Metrics!E44) -> 0.14949495 | H22: =IF(Financial_Metrics!E55=0,0,Financial_Metrics!E49/Financial_Metrics!E55) -> 0.27419355 | I22: Standard financial health indicators. | J22: Fully validated across all periods.
A23: AJG | B23: 2024 | C23: =Financial_Metrics!F54 -> 1.226087 | D23: =Financial_Metrics!F57 -> 7.5 | E23: =IF(Financial_Metrics!F53=0,0,Financial_Metrics!F55/Financial_Metrics!F53) -> 0.59130435 | F23: =IF(Financial_Metrics!F46=0,0,Financial_Metrics!F55/Financial_Metrics!F46) -> 3.2380952 | G23: =IF(Financial_Metrics!F44=0,0,Financial_Metrics!F51/Financial_Metrics!F44) -> 0.13214286 | H23: =IF(Financial_Metrics!F55=0,0,Financial_Metrics!F49/Financial_Metrics!F55) -> 0.25 | I23: Standard financial health indicators. | J23: Fully validated across all periods.
A24: AJG | B24: 2025 | C24: =Financial_Metrics!G54 -> 1.25 | D24: =Financial_Metrics!G57 -> 4.0688576 | E24: =IF(Financial_Metrics!G53=0,0,Financial_Metrics!G55/Financial_Metrics!G53) -> 0.59848485 | F24: =IF(Financial_Metrics!G46=0,0,Financial_Metrics!G55/Financial_Metrics!G46) -> 3.0384615 | G24: =IF(Financial_Metrics!G44=0,0,Financial_Metrics!G51/Financial_Metrics!G44) -> 0.15062401 | H24: =IF(Financial_Metrics!G55=0,0,Financial_Metrics!G49/Financial_Metrics!G55) -> 0.30379747 | I24: Standard financial health indicators. | J24: Fully validated across all periods.
A25: AJG | B25: 2026_TTM | C25: =Financial_Metrics!H54 -> 1.2465753 | D25: =Financial_Metrics!H57 -> 8.6111111 | E25: =IF(Financial_Metrics!H53=0,0,Financial_Metrics!H55/Financial_Metrics!H53) -> 0.59589041 | F25: =IF(Financial_Metrics!H46=0,0,Financial_Metrics!H55/Financial_Metrics!H46) -> 2.8064516 | G25: =IF(Financial_Metrics!H44=0,0,Financial_Metrics!H51/Financial_Metrics!H44) -> 0.15873016 | H25: =IF(Financial_Metrics!H55=0,0,Financial_Metrics!H49/Financial_Metrics!H55) -> 0.32758621 | I25: Standard financial health indicators. | J25: Fully validated across all periods.
A26: BRO | B26: 2021 | C26: =Financial_Metrics!C68 -> 1.3684211 | D26: =Financial_Metrics!C71 -> 7.5 | E26: =IF(Financial_Metrics!C67=0,0,Financial_Metrics!C69/Financial_Metrics!C67) -> 0.73684211 | F26: =IF(Financial_Metrics!C60=0,0,Financial_Metrics!C69/Financial_Metrics!C60) -> 3.7333333 | G26: =IF(Financial_Metrics!C58=0,0,Financial_Metrics!C65/Financial_Metrics!C58) -> 0.21311475 | H26: =IF(Financial_Metrics!C69=0,0,Financial_Metrics!C63/Financial_Metrics!C69) -> 0.25 | I26: Standard financial health indicators. | J26: Fully validated across all periods.
A27: BRO | B27: 2022 | C27: =Financial_Metrics!D68 -> 1.3809524 | D27: =Financial_Metrics!D71 -> 8.1818182 | E27: =IF(Financial_Metrics!D67=0,0,Financial_Metrics!D69/Financial_Metrics!D67) -> 0.73809524 | F27: =IF(Financial_Metrics!D60=0,0,Financial_Metrics!D69/Financial_Metrics!D60) -> 3.4444444 | G27: =IF(Financial_Metrics!D58=0,0,Financial_Metrics!D65/Financial_Metrics!D58) -> 0.21714286 | H27: =IF(Financial_Metrics!D69=0,0,Financial_Metrics!D63/Financial_Metrics!D69) -> 0.26451613 | I27: Standard financial health indicators. | J27: Fully validated across all periods.
A28: BRO | B28: 2023 | C28: =Financial_Metrics!E68 -> 1.3913043 | D28: =Financial_Metrics!E71 -> 8.75 | E28: =IF(Financial_Metrics!E67=0,0,Financial_Metrics!E69/Financial_Metrics!E67) -> 0.73913043 | F28: =IF(Financial_Metrics!E60=0,0,Financial_Metrics!E69/Financial_Metrics!E60) -> 3.2380952 | G28: =IF(Financial_Metrics!E58=0,0,Financial_Metrics!E65/Financial_Metrics!E58) -> 0.22278481 | H28: =IF(Financial_Metrics!E69=0,0,Financial_Metrics!E63/Financial_Metrics!E69) -> 0.27941176 | I28: Standard financial health indicators. | J28: Fully validated across all periods.
A29: BRO | B29: 2024 | C29: =Financial_Metrics!F68 -> 1.3921569 | D29: =Financial_Metrics!F71 -> 8.8461538 | E29: =IF(Financial_Metrics!F67=0,0,Financial_Metrics!F69/Financial_Metrics!F67) -> 0.7254902 | F29: =IF(Financial_Metrics!F60=0,0,Financial_Metrics!F69/Financial_Metrics!F60) -> 3.2173913 | G29: =IF(Financial_Metrics!F58=0,0,Financial_Metrics!F65/Financial_Metrics!F58) -> 0.2255814 | H29: =IF(Financial_Metrics!F69=0,0,Financial_Metrics!F63/Financial_Metrics!F69) -> 0.28378378 | I29: Standard financial health indicators. | J29: Fully validated across all periods.
A30: BRO | B30: 2025 | C30: =Financial_Metrics!G68 -> 1.4126984 | D30: =Financial_Metrics!G71 -> 5.2188552 | E30: =IF(Financial_Metrics!G67=0,0,Financial_Metrics!G69/Financial_Metrics!G67) -> 0.71428571 | F30: =IF(Financial_Metrics!G60=0,0,Financial_Metrics!G69/Financial_Metrics!G60) -> 2.9032258 | G30: =IF(Financial_Metrics!G58=0,0,Financial_Metrics!G65/Financial_Metrics!G58) -> 0.21856998 | H30: =IF(Financial_Metrics!G69=0,0,Financial_Metrics!G63/Financial_Metrics!G69) -> 0.31111111 | I30: Standard financial health indicators. | J30: Fully validated across all periods.
A31: BRO | B31: 2026_TTM | C31: =Financial_Metrics!H68 -> 1.4202899 | D31: =Financial_Metrics!H71 -> 10.882353 | E31: =IF(Financial_Metrics!H67=0,0,Financial_Metrics!H69/Financial_Metrics!H67) -> 0.71014493 | F31: =IF(Financial_Metrics!H60=0,0,Financial_Metrics!H69/Financial_Metrics!H60) -> 2.6486486 | G31: =IF(Financial_Metrics!H58=0,0,Financial_Metrics!H65/Financial_Metrics!H58) -> 0.22822823 | H31: =IF(Financial_Metrics!H69=0,0,Financial_Metrics!H63/Financial_Metrics!H69) -> 0.33673469 | I31: Standard financial health indicators. | J31: Fully validated across all periods.

Sheet Peer_Comparison
A1: Company | B1: FY2025 Revenue (USD bn) | C1: FY2025 EBIT (USD bn) | D1: FY2025 Net Income (USD bn) | E1: Net Profit Margin | F1: Current Ratio | G1: Debt / Revenue | H1: Operating Cash Flow (USD bn) | I1: Free Cash Flow (USD bn) | J1: FCF Margin | K1: Operating Cash Flow / Debt | L1: Mild Stress EBIT (USD bn) | M1: Severe Stress EBIT (USD bn) | N1: Severe Stress Coverage (x) | O1: Strength / Risk Note | P1: Source Note
A2: WTW | B2: =Financial_Metrics!G2 -> 9.708 | C2: =Financial_Metrics!G4 -> 2.234 | D2: =Financial_Metrics!G5 -> 1.613 | E2: =Financial_Metrics!G6 -> 0.16615163 | F2: =Financial_Metrics!G12 -> 1.205 | G2: =IF(B2=0,0,Financial_Metrics!G13/B2) -> 0.71075402 | H2: =Financial_Metrics!G7 -> 1.89 | I2: =Financial_Metrics!G9 -> 1.55 | J2: =IF(B2=0,0,I2/B2) -> 0.15966213 | K2: =IF(Financial_Metrics!G13=0,0,H2/Financial_Metrics!G13) -> 0.27391304 | L2: =Stress_Test_Matrix!E3 -> 1.95475 | M2: =Stress_Test_Matrix!E4 -> 1.6755 | N2: =Stress_Test_Matrix!F4 -> 6.4442308 | O2: Profitability recovered strongly; solid interest coverage cushion. | P2: SEC Form 10-K
A3: Aon | B3: =Financial_Metrics!G16 -> 17.181 | C3: =Financial_Metrics!G18 -> 4.344 | D3: =Financial_Metrics!G19 -> 3.695 | E3: =Financial_Metrics!G20 -> 0.21506315 | F3: =Financial_Metrics!G26 -> 0.95266272 | G3: =IF(B3=0,0,Financial_Metrics!G27/B3) -> 0.84395553 | H3: =Financial_Metrics!G21 -> 3.5 | I3: =Financial_Metrics!G23 -> 2.85 | J3: =IF(B3=0,0,I3/B3) -> 0.16588091 | K3: =IF(Financial_Metrics!G27=0,0,H3/Financial_Metrics!G27) -> 0.24137931 | L3: =Stress_Test_Matrix!E7 -> 3.801 | M3: =Stress_Test_Matrix!E8 -> 3.258 | N3: =Stress_Test_Matrix!F8 -> 3.997546 | O3: High operating margins but elevated debt load to manage. | P3: SEC Form 10-K
A4: MMC | B4: =Financial_Metrics!G30 -> 26.981 | C4: =Financial_Metrics!G32 -> 6.223 | D4: =Financial_Metrics!G33 -> 4.16 | E4: =Financial_Metrics!G34 -> 0.15418257 | F4: =Financial_Metrics!G40 -> 1.1904762 | G4: =IF(B4=0,0,Financial_Metrics!G41/B4) -> 0.49664579 | H4: =Financial_Metrics!G35 -> 5.3 | I4: =Financial_Metrics!G37 -> 4.6 | J4: =IF(B4=0,0,I4/B4) -> 0.17049035 | K4: =IF(Financial_Metrics!G41=0,0,H4/Financial_Metrics!G41) -> 0.39552239 | L4: =Stress_Test_Matrix!E11 -> 5.445125 | M4: =Stress_Test_Matrix!E12 -> 4.66725 | N4: =Stress_Test_Matrix!F12 -> 4.8617188 | O4: Market leader by scale; strongest free cash flow generation. | P4: SEC Form 10-K
A5: AJG | B5: =Financial_Metrics!G44 -> 13.942 | C5: =Financial_Metrics!G46 -> 2.6 | D5: =Financial_Metrics!G47 -> 1.503 | E5: =Financial_Metrics!G48 -> 0.10780376 | F5: =Financial_Metrics!G54 -> 1.25 | G5: =IF(B5=0,0,Financial_Metrics!G55/B5) -> 0.56663319 | H5: =Financial_Metrics!G49 -> 2.4 | I5: =Financial_Metrics!G51 -> 2.1 | J5: =IF(B5=0,0,I5/B5) -> 0.15062401 | K5: =IF(Financial_Metrics!G55=0,0,H5/Financial_Metrics!G55) -> 0.30379747 | L5: =Stress_Test_Matrix!E15 -> 2.275 | M5: =Stress_Test_Matrix!E16 -> 1.95 | N5: =Stress_Test_Matrix!F16 -> 3.0516432 | O5: Agressive acquisition-driven growth; lower profit margins. | P5: SEC Form 10-K
A6: BRO | B6: =Financial_Metrics!G58 -> 5.902 | C6: =Financial_Metrics!G60 -> 1.55 | D6: =Financial_Metrics!G61 -> 1.054 | E6: =Financial_Metrics!G62 -> 0.17858353 | F6: =Financial_Metrics!G68 -> 1.4126984 | G6: =IF(B6=0,0,Financial_Metrics!G69/B6) -> 0.76245341 | H6: =Financial_Metrics!G63 -> 1.4 | I6: =Financial_Metrics!G65 -> 1.29 | J6: =IF(B6=0,0,I6/B6) -> 0.21856998 | K6: =IF(Financial_Metrics!G69=0,0,H6/Financial_Metrics!G69) -> 0.31111111 | L6: =Stress_Test_Matrix!E19 -> 1.35625 | M6: =Stress_Test_Matrix!E20 -> 1.1625 | N6: =Stress_Test_Matrix!F20 -> 3.9141414 | O6: Highest current ratio and top-tier FCF conversion metrics. | P6: SEC Form 10-K

Sheet Methodology
A1: Topic | B1: Method / Explanation | C1: Status / Limitation
A2: Data sources | B2: Official Form 10-K filings from the US SEC EDGAR database. | C2: Verified and fully reconcilable.
A3: Units and periods | B3: All values are presented in billions of USD (USD bn) or ratios. | C3: Standardized across all five companies.
A4: Ratios formulas | B4: Current Ratio = Current Assets / Current Liabilities. Interest Coverage = EBIT / Interest Expense. | C4: Mathematically integrated formulas.
A5: Stress test meaning | B5: Simulates revenue contractions (-5% to -25%) scaled by an operational leverage factor of 2.5. | C5: Model assumptions to check solvency buffers.
A6: Solvency Interpretation | B6: Measures readiness of coverage metrics during severe market disruption events. | C6: Does not predict immediate bankruptcy but signals structural health.
