Workbook

Sheet Summary
A1: Insurance Brokers Peer Model — Summary
A2: FY2025 snapshot, USD bn unless stated. Every figure links to the model sheets. Several inputs are still unverified — see Review_Flags before drawing conclusions.
A4: Company | B4: Revenue | C4: EBIT | D4: Net margin | E4: FCF margin | F4: Current ratio | G4: Interest coverage FY2025 (x) | H4: Severe-stress coverage (x) | I4: Severe-stress assessment | J4: EBIT basis
A5: =Peer_Comparison!A2 -> WTW | B5: =Peer_Comparison!B2 -> 9.708 | C5: =Peer_Comparison!C2 -> 2.234 | D5: =Peer_Comparison!E2 -> 0.16532756 | E5: =Peer_Comparison!J2 -> 0.1592501 | F5: =Peer_Comparison!F2 -> 1.2049414 | G5: =Financial_Ratios!D6 -> 8.5923077 | H5: =Peer_Comparison!N2 -> 6.4442308 | I5: =Stress_Test_Matrix!G4 -> Illustrative buffer | J5: =IF(ISNUMBER(SEARCH("proxy",Peer_Comparison!K2)),"Derived proxy","Reported") -> Reported
A6: =Peer_Comparison!A3 -> Aon | B6: =Peer_Comparison!B3 -> 17.181 | C6: =Peer_Comparison!C3 -> 4.344 | D6: =Peer_Comparison!E3 -> 0.21506315 | E6: =Peer_Comparison!J3 -> 0.16588091 | F6: =Peer_Comparison!F3 -> 0.95266272 | G6: =Financial_Ratios!D12 -> 5.3300613 | H6: =Peer_Comparison!N3 -> 3.997546 | I6: =Stress_Test_Matrix!G8 -> Pressure | J6: =IF(ISNUMBER(SEARCH("proxy",Peer_Comparison!K3)),"Derived proxy","Reported") -> Reported
A7: =Peer_Comparison!A4 -> MMC | B7: =Peer_Comparison!B4 -> 26.981 | C7: =Peer_Comparison!C4 -> 6.223 | D7: =Peer_Comparison!E4 -> 0.15418257 | E7: =Peer_Comparison!J4 -> 0.17049035 | F7: =Peer_Comparison!F4 -> 1.1904762 | G7: =Financial_Ratios!D18 -> 6.4822917 | H7: =Peer_Comparison!N4 -> 4.8617187 | I7: =Stress_Test_Matrix!G12 -> Pressure | J7: =IF(ISNUMBER(SEARCH("proxy",Peer_Comparison!K4)),"Derived proxy","Reported") -> Reported
A8: =Peer_Comparison!A5 -> AJG | B8: =Peer_Comparison!B5 -> 13.942 | C8: =Peer_Comparison!C5 -> 2.51 | D8: =Peer_Comparison!E5 -> 0.10715823 | E8: =Peer_Comparison!J5 -> 0.15062401 | F8: =Peer_Comparison!F5 -> 1.25 | G8: =Financial_Ratios!D24 -> 3.9280125 | H8: =Peer_Comparison!N5 -> 2.9460094 | I8: =Stress_Test_Matrix!G16 -> Pressure | J8: =IF(ISNUMBER(SEARCH("proxy",Peer_Comparison!K5)),"Derived proxy","Reported") -> Derived proxy
A9: =Peer_Comparison!A6 -> BRO | B9: =Peer_Comparison!B6 -> 5.902 | C9: =Peer_Comparison!C6 -> 1.668 | D9: =Peer_Comparison!E6 -> 0.17858353 | E9: =Peer_Comparison!J6 -> 0.21856998 | F9: =Peer_Comparison!F6 -> 1.4126984 | G9: =Financial_Ratios!D30 -> 5.6161616 | H9: =Peer_Comparison!N6 -> 4.2121212 | I9: =Stress_Test_Matrix!G20 -> Pressure | J9: =IF(ISNUMBER(SEARCH("proxy",Peer_Comparison!K6)),"Derived proxy","Reported") -> Derived proxy
A10: Peer median | B10: =MEDIAN(B5:B9) -> 13.942 | C10: =MEDIAN(C5:C9) -> 2.51 | D10: =MEDIAN(D5:D9) -> 0.16532756 | E10: =MEDIAN(E5:E9) -> 0.16588091 | F10: =MEDIAN(F5:F9) -> 1.2049414 | G10: =MEDIAN(G5:G9) -> 5.6161616 | H10: =MEDIAN(H5:H9) -> 4.2121212
A11: Median is across five companies and is descriptive only. AJG and BRO EBIT is a derived proxy, so EBIT-based figures are not strictly like-for-like.
A13: Data-quality scorecard — Financial_Metrics rows by status | H13: Verification progress — Source_Verification
A14: Company | B14: Needs review | C14: Partially verified | D14: Derived proxy | E14: Calculated | F14: Total rows | H14: Company | I14: Checked to primary | J14: Corrected | K14: Secondary discrepancies
A15: =A5 -> WTW | B15: =COUNTIFS(Financial_Metrics!$A$2:$A$71,$A15,Financial_Metrics!$J$2:$J$71,"Needs review*") -> 0 | C15: =COUNTIFS(Financial_Metrics!$A$2:$A$71,$A15,Financial_Metrics!$J$2:$J$71,"Partially verified*") -> 9 | D15: =COUNTIFS(Financial_Metrics!$A$2:$A$71,$A15,Financial_Metrics!$J$2:$J$71,"Derived proxy*") -> 0 | E15: =COUNTIFS(Financial_Metrics!$A$2:$A$71,$A15,Financial_Metrics!$J$2:$J$71,"Calculated*") -> 5 | F15: =SUM(B15:E15) -> 14 | H15: =A5 -> WTW | I15: =COUNTIFS(Source_Verification!$A$5:$A$51,$H15,Source_Verification!$K$5:$K$51,"Verified*")+COUNTIFS(Source_Verification!$A$5:$A$51,$H15,Source_Verification!$K$5:$K$51,"Corrected*") -> 24 | J15: =COUNTIFS(Source_Verification!$A$5:$A$51,$H15,Source_Verification!$K$5:$K$51,"Corrected*") -> 10 | K15: =COUNTIFS(Source_Verification!$A$5:$A$51,$H15,Source_Verification!$K$5:$K$51,"Discrepancy*") -> 19
A16: =A6 -> Aon | B16: =COUNTIFS(Financial_Metrics!$A$2:$A$71,$A16,Financial_Metrics!$J$2:$J$71,"Needs review*") -> 5 | C16: =COUNTIFS(Financial_Metrics!$A$2:$A$71,$A16,Financial_Metrics!$J$2:$J$71,"Partially verified*") -> 4 | D16: =COUNTIFS(Financial_Metrics!$A$2:$A$71,$A16,Financial_Metrics!$J$2:$J$71,"Derived proxy*") -> 0 | E16: =COUNTIFS(Financial_Metrics!$A$2:$A$71,$A16,Financial_Metrics!$J$2:$J$71,"Calculated*") -> 5 | F16: =SUM(B16:E16) -> 14 | H16: =A6 -> Aon | I16: =COUNTIFS(Source_Verification!$A$5:$A$51,$H16,Source_Verification!$K$5:$K$51,"Verified*")+COUNTIFS(Source_Verification!$A$5:$A$51,$H16,Source_Verification!$K$5:$K$51,"Corrected*") -> 0 | J16: =COUNTIFS(Source_Verification!$A$5:$A$51,$H16,Source_Verification!$K$5:$K$51,"Corrected*") -> 0 | K16: =COUNTIFS(Source_Verification!$A$5:$A$51,$H16,Source_Verification!$K$5:$K$51,"Discrepancy*") -> 0
A17: =A7 -> MMC | B17: =COUNTIFS(Financial_Metrics!$A$2:$A$71,$A17,Financial_Metrics!$J$2:$J$71,"Needs review*") -> 5 | C17: =COUNTIFS(Financial_Metrics!$A$2:$A$71,$A17,Financial_Metrics!$J$2:$J$71,"Partially verified*") -> 4 | D17: =COUNTIFS(Financial_Metrics!$A$2:$A$71,$A17,Financial_Metrics!$J$2:$J$71,"Derived proxy*") -> 0 | E17: =COUNTIFS(Financial_Metrics!$A$2:$A$71,$A17,Financial_Metrics!$J$2:$J$71,"Calculated*") -> 5 | F17: =SUM(B17:E17) -> 14 | H17: =A7 -> MMC | I17: =COUNTIFS(Source_Verification!$A$5:$A$51,$H17,Source_Verification!$K$5:$K$51,"Verified*")+COUNTIFS(Source_Verification!$A$5:$A$51,$H17,Source_Verification!$K$5:$K$51,"Corrected*") -> 0 | J17: =COUNTIFS(Source_Verification!$A$5:$A$51,$H17,Source_Verification!$K$5:$K$51,"Corrected*") -> 0 | K17: =COUNTIFS(Source_Verification!$A$5:$A$51,$H17,Source_Verification!$K$5:$K$51,"Discrepancy*") -> 0
A18: =A8 -> AJG | B18: =COUNTIFS(Financial_Metrics!$A$2:$A$71,$A18,Financial_Metrics!$J$2:$J$71,"Needs review*") -> 5 | C18: =COUNTIFS(Financial_Metrics!$A$2:$A$71,$A18,Financial_Metrics!$J$2:$J$71,"Partially verified*") -> 3 | D18: =COUNTIFS(Financial_Metrics!$A$2:$A$71,$A18,Financial_Metrics!$J$2:$J$71,"Derived proxy*") -> 1 | E18: =COUNTIFS(Financial_Metrics!$A$2:$A$71,$A18,Financial_Metrics!$J$2:$J$71,"Calculated*") -> 5 | F18: =SUM(B18:E18) -> 14 | H18: =A8 -> AJG | I18: =COUNTIFS(Source_Verification!$A$5:$A$51,$H18,Source_Verification!$K$5:$K$51,"Verified*")+COUNTIFS(Source_Verification!$A$5:$A$51,$H18,Source_Verification!$K$5:$K$51,"Corrected*") -> 0 | J18: =COUNTIFS(Source_Verification!$A$5:$A$51,$H18,Source_Verification!$K$5:$K$51,"Corrected*") -> 0 | K18: =COUNTIFS(Source_Verification!$A$5:$A$51,$H18,Source_Verification!$K$5:$K$51,"Discrepancy*") -> 0
A19: =A9 -> BRO | B19: =COUNTIFS(Financial_Metrics!$A$2:$A$71,$A19,Financial_Metrics!$J$2:$J$71,"Needs review*") -> 5 | C19: =COUNTIFS(Financial_Metrics!$A$2:$A$71,$A19,Financial_Metrics!$J$2:$J$71,"Partially verified*") -> 3 | D19: =COUNTIFS(Financial_Metrics!$A$2:$A$71,$A19,Financial_Metrics!$J$2:$J$71,"Derived proxy*") -> 1 | E19: =COUNTIFS(Financial_Metrics!$A$2:$A$71,$A19,Financial_Metrics!$J$2:$J$71,"Calculated*") -> 5 | F19: =SUM(B19:E19) -> 14 | H19: =A9 -> BRO | I19: =COUNTIFS(Source_Verification!$A$5:$A$51,$H19,Source_Verification!$K$5:$K$51,"Verified*")+COUNTIFS(Source_Verification!$A$5:$A$51,$H19,Source_Verification!$K$5:$K$51,"Corrected*") -> 0 | J19: =COUNTIFS(Source_Verification!$A$5:$A$51,$H19,Source_Verification!$K$5:$K$51,"Corrected*") -> 0 | K19: =COUNTIFS(Source_Verification!$A$5:$A$51,$H19,Source_Verification!$K$5:$K$51,"Discrepancy*") -> 0
A20: Total | B20: =SUM(B15:B19) -> 20 | C20: =SUM(C15:C19) -> 23 | D20: =SUM(D15:D19) -> 2 | E20: =SUM(E15:E19) -> 25 | F20: =SUM(F15:F19) -> 70 | H20: Total | I20: =SUM(I15:I19) -> 24 | J20: =SUM(J15:J19) -> 10 | K20: =SUM(K15:K19) -> 19
A21: Input rows still marked “Needs review” | B21: =IFERROR(B20/SUM(B20:D20),"") -> 0.44444444 | C21: Excludes Calculated rows, which depend on those inputs. | H21: Only WTW has been checked so far; the other four show 0 until verified.
A23: Review flags
A24: Flags logged | B24: =COUNTA(Review_Flags!$A$2:$A$20) -> 19
A25: Open | B25: =COUNTIF(Review_Flags!$F$2:$F$20,"Open") -> 11
A26: High priority and open | B26: =COUNTIFS(Review_Flags!$A$2:$A$20,"High",Review_Flags!$F$2:$F$20,"Open") -> 8

Sheet Financial_Metrics
A1: Company | B1: Metric (USD bn unless ratio / %) | C1: 2021 | D1: 2022 | E1: 2023 | F1: 2024 | G1: 2025 | H1: 2026_TTM | I1: Source URL | J1: Data Status | K1: Review Notes | M1: Legend
A2: WTW | B2: Total Revenue | C2: 9 | D2: 8.87 | E2: 9.483 | F2: 9.93 | G2: 9.708 | H2: 10.1 | I2: https://www.sec.gov/Archives/edgar/data/1140536/000119312526069307/wtw-20251231.htm | J2: Partially verified — FY2023–FY2025 | K2: FY2023–FY2025 values reconciled to cited FY2025 Form 10-K. 2021–2022 and 2026_TTM are not verified in this pass; see Audit_Log. | M2: Blue = hardcoded input
A3: WTW | B3: Revenue Growth YoY | C3: n/a | D3: =IFERROR(D2/C2-1,"") -> -0.014444444 | E3: =IFERROR(E2/D2-1,"") -> 0.069109357 | F3: =IFERROR(F2/E2-1,"") -> 0.047136982 | G3: =IFERROR(G2/F2-1,"") -> -0.022356495 | H3: n/a — TTM comparator unavailable | I3: Calculated | J3: Calculated (FY only) | K3: FY2024 and FY2025 growth use the reconciled FY2023–FY2025 revenue series. FY2023 growth still depends on the unverified FY2022 input. 2026_TTM growth is intentionally n/a because no prior comparable TTM period is provided. | M3: Black = formula
A4: WTW | B4: Operating Income (EBIT) | C4: 1.75 | D4: 1.81 | E4: 1.365 | F4: 0.627 | G4: 2.234 | H4: 1.77 | I4: https://www.sec.gov/Archives/edgar/data/1140536/000119312526069307/wtw-20251231.htm | J4: Partially verified — FY2023–FY2025 | K4: FY2023–FY2025 values reconciled to cited FY2025 Form 10-K. 2021–2022 and 2026_TTM are not verified in this pass; see Audit_Log.
A5: WTW | B5: Net Income | C5: 4.22 | D5: 1.01 | E5: 1.055 | F5: -0.098 | G5: 1.605 | H5: 1.56 | I5: https://www.sec.gov/Archives/edgar/data/1140536/000119312526069307/wtw-20251231.htm | J5: Partially verified — FY2023–FY2025 | K5: FY2023–FY2025 reconciled to WTW FY2025 Form 10-K, net income attributable to WTW (checked 2026-10-28). FY2023 was 1.064 (consolidated net income) and is now 1.055 (attributable). 2021–2022 match secondary sources after rounding; 2026_TTM not verified. | M5: Status colours (column J)
A6: WTW | B6: Net Profit Margin | C6: =IFERROR(C5/C2,"") -> 0.46888889 | D6: =IFERROR(D5/D2,"") -> 0.11386697 | E6: =IFERROR(E5/E2,"") -> 0.11125171 | F6: =IFERROR(F5/F2,"") -> -0.0098690836 | G6: =IFERROR(G5/G2,"") -> 0.16532756 | H6: =IFERROR(H5/H2,"") -> 0.15445545 | I6: Calculated | J6: Calculated — inputs require review | K6: Formula is live; output reliability depends on source inputs. See Audit_Log for source status. | M6: Needs review
A7: WTW | B7: Operating Cash Flow | C7: 2.11 | D7: 0.97 | E7: 1.345 | F7: 1.512 | G7: 1.775 | H7: 2.04 | I7: https://www.sec.gov/Archives/edgar/data/1140536/000119312526069307/wtw-20251231.htm | J7: Partially verified — FY2023–FY2025 | K7: FY2023–FY2025 reconciled to WTW FY2025 Form 10-K cash-flow statement (checked 2026-10-28). 2021–2022 differ from secondary sources (2.061 / 0.812) and are not changed until checked to primary filings. 2026_TTM period end is undefined; see Source_Verification. | M7: Partially verified
A8: WTW | B8: Capital Expenditures | C8: 0.28 | D8: 0.3 | E8: 0.242 | F8: 0.245 | G8: 0.229 | H8: 0.35 | I8: https://www.sec.gov/Archives/edgar/data/1140536/000119312526069307/wtw-20251231.htm | J8: Partially verified — FY2023–FY2025 | K8: FY2023–FY2025 reconciled to the cash-flow line 'Additions to fixed assets and software' (checked 2026-10-28). 2021–2022 differ from secondary sources (0.201 / 0.204) and are not changed yet. | M8: Derived proxy
A9: WTW | B9: Free Cash Flow | C9: =IFERROR(C7-C8,"") -> 1.83 | D9: =IFERROR(D7-D8,"") -> 0.67 | E9: =IFERROR(E7-E8,"") -> 1.103 | F9: =IFERROR(F7-F8,"") -> 1.267 | G9: =IFERROR(G7-G8,"") -> 1.546 | H9: =IFERROR(H7-H8,"") -> 1.69 | I9: Calculated | J9: Calculated — inputs require review | K9: Formula is live; output reliability depends on source inputs. See Audit_Log for source status. | M9: Calculated
A10: WTW | B10: Current Assets | C10: 13.5 | D10: 13.83 | E10: 14.06 | F10: 15.105 | G10: 16.874 | H10: 16.75 | I10: https://www.sec.gov/Archives/edgar/data/1140536/000119312526069307/wtw-20251231.htm | J10: Partially verified — FY2024–FY2025 | K10: FY2024–FY2025 reconciled to the FY2025 Form 10-K balance sheet (includes fiduciary assets). FY2021–FY2023 differ from secondary sources (13.433 / 15.835 / 18.488 mn basis) and need the older 10-Ks.
A11: WTW | B11: Current Liabilities | C11: 12.6 | D11: 12.93 | E11: 13.26 | F11: 12.598 | G11: 14.004 | H11: 15.25 | I11: https://www.sec.gov/Archives/edgar/data/1140536/000119312526069307/wtw-20251231.htm | J11: Partially verified — FY2024–FY2025 | K11: FY2024–FY2025 reconciled to the FY2025 Form 10-K balance sheet (includes fiduciary liabilities). FY2021–FY2023 differ from secondary sources and need the older 10-Ks.
A12: WTW | B12: Current Ratio | C12: =IFERROR(C10/C11,"") -> 1.0714286 | D12: =IFERROR(D10/D11,"") -> 1.0696056 | E12: =IFERROR(E10/E11,"") -> 1.0603318 | F12: =IFERROR(F10/F11,"") -> 1.1989998 | G12: =IFERROR(G10/G11,"") -> 1.2049414 | H12: =IFERROR(H10/H11,"") -> 1.0983607 | I12: Calculated | J12: Calculated — inputs require review | K12: Formula is live; output reliability depends on source inputs. See Audit_Log for source status.
A13: WTW | B13: Total Debt | C13: 5.49 | D13: 5.48 | E13: 5.95 | F13: 5.929 | G13: 6.903 | H13: 7.1 | I13: https://www.sec.gov/Archives/edgar/data/1140536/000119312526069307/wtw-20251231.htm | J13: Partially verified — FY2024–FY2025 | K13: FY2024–FY2025 = current debt + long-term debt + lease liabilities, per the FY2025 10-K balance sheet (excluding leases: 5.309 / 6.306). FY2021–FY2023 are not reconciled. Definition choice is open: see Review_Flags.
A14: WTW | B14: Interest Expense | C14: 0.28 | D14: 0.3 | E14: 0.235 | F14: 0.263 | G14: 0.26 | H14: 0.34 | I14: https://www.sec.gov/Archives/edgar/data/1140536/000119312526069307/wtw-20251231.htm | J14: Partially verified — FY2023–FY2025 | K14: FY2023–FY2025 reconciled to the FY2025 Form 10-K income statement (checked 2026-10-28). FY2023 was 0.30 in the previous version; the filing shows 0.235. 2021–2022 differ from secondary sources (0.211 / 0.208).
A15: WTW | B15: Interest Coverage Ratio | C15: =IFERROR(C4/C14,"") -> 6.25 | D15: =IFERROR(D4/D14,"") -> 6.0333333 | E15: =IFERROR(E4/E14,"") -> 5.8085106 | F15: =IFERROR(F4/F14,"") -> 2.3840304 | G15: =IFERROR(G4/G14,"") -> 8.5923077 | H15: =IFERROR(H4/H14,"") -> 5.2058824 | I15: Calculated | J15: Calculated — inputs require review | K15: Formula is live; output reliability depends on source inputs. See Audit_Log for source status.
A16: Aon | B16: Total Revenue | C16: 12.2 | D16: 12.5 | E16: 13.376 | F16: 15.698 | G16: 17.181 | H16: 17.58 | I16: https://www.sec.gov/Archives/edgar/data/315293/000162828026008116/aon-20251231.htm | J16: Partially verified — FY2023–FY2025 | K16: FY2023–FY2025 values reconciled to cited FY2025 Form 10-K. 2021–2022 and 2026_TTM are not verified in this pass; see Audit_Log.
A17: Aon | B17: Revenue Growth YoY | C17: n/a | D17: =IFERROR(D16/C16-1,"") -> 0.024590164 | E17: =IFERROR(E16/D16-1,"") -> 0.07008 | F17: =IFERROR(F16/E16-1,"") -> 0.1735945 | G17: =IFERROR(G16/F16-1,"") -> 0.094470633 | H17: n/a — TTM comparator unavailable | I17: Calculated | J17: Calculated (FY only) | K17: FY2024 and FY2025 growth use the reconciled FY2023–FY2025 revenue series. FY2023 growth still depends on the unverified FY2022 input. 2026_TTM growth is intentionally n/a because no prior comparable TTM period is provided.
A18: Aon | B18: Operating Income (EBIT) | C18: 3.1 | D18: 3.2 | E18: 3.785 | F18: 3.835 | G18: 4.344 | H18: 4.2 | I18: https://www.sec.gov/Archives/edgar/data/315293/000162828026008116/aon-20251231.htm | J18: Partially verified — FY2023–FY2025 | K18: FY2023–FY2025 values reconciled to cited FY2025 Form 10-K. 2021–2022 and 2026_TTM are not verified in this pass; see Audit_Log.
A19: Aon | B19: Net Income | C19: 2.4 | D19: 2.6 | E19: 2.564 | F19: 2.654 | G19: 3.695 | H19: 3.91 | I19: https://www.sec.gov/Archives/edgar/data/315293/000162828026008116/aon-20251231.htm | J19: Partially verified — FY2023–FY2025 | K19: FY2023–FY2025 values reconciled to cited FY2025 Form 10-K. 2021–2022 and 2026_TTM are not verified in this pass; see Audit_Log.
A20: Aon | B20: Net Profit Margin | C20: =IFERROR(C19/C16,"") -> 0.19672131 | D20: =IFERROR(D19/D16,"") -> 0.208 | E20: =IFERROR(E19/E16,"") -> 0.1916866 | F20: =IFERROR(F19/F16,"") -> 0.16906612 | G20: =IFERROR(G19/G16,"") -> 0.21506315 | H20: =IFERROR(H19/H16,"") -> 0.22241183 | I20: Calculated | J20: Calculated — inputs require review | K20: Formula is live; output reliability depends on source inputs. See Audit_Log for source status.
A21: Aon | B21: Operating Cash Flow | C21: 2.6 | D21: 2.8 | E21: 3.1 | F21: 3.2 | G21: 3.5 | H21: 3.8 | I21: https://www.sec.gov/Archives/edgar/data/315293/000162828026008116/aon-20251231.htm | J21: Needs review | K21: Historical and TTM values have not all been reconciled to the cash-flow statement; do not treat as confirmed.
A22: Aon | B22: Capital Expenditures | C22: 0.4 | D22: 0.45 | E22: 0.5 | F22: 0.55 | G22: 0.65 | H22: 0.73 | I22: https://www.sec.gov/Archives/edgar/data/315293/000162828026008116/aon-20251231.htm | J22: Needs review | K22: Historical and TTM values have not all been reconciled to the cash-flow statement; do not treat as confirmed.
A23: Aon | B23: Free Cash Flow | C23: =IFERROR(C21-C22,"") -> 2.2 | D23: =IFERROR(D21-D22,"") -> 2.35 | E23: =IFERROR(E21-E22,"") -> 2.6 | F23: =IFERROR(F21-F22,"") -> 2.65 | G23: =IFERROR(G21-G22,"") -> 2.85 | H23: =IFERROR(H21-H22,"") -> 3.07 | I23: Calculated | J23: Calculated — inputs require review | K23: Formula is live; output reliability depends on source inputs. See Audit_Log for source status.
A24: Aon | B24: Current Assets | C24: 14.1 | D24: 14.5 | E24: 15.1 | F24: 15.8 | G24: 16.1 | H24: 16.5 | I24: https://www.sec.gov/Archives/edgar/data/315293/000162828026008116/aon-20251231.htm | J24: Needs review | K24: Not independently reconciled to the corresponding balance-sheet line items in this pass. Ratios using this row are provisional.
A25: Aon | B25: Current Liabilities | C25: 15.2 | D25: 15.5 | E25: 16.2 | F25: 16.5 | G25: 16.9 | H25: 17.1 | I25: https://www.sec.gov/Archives/edgar/data/315293/000162828026008116/aon-20251231.htm | J25: Needs review | K25: Not independently reconciled to the corresponding balance-sheet line items in this pass. Ratios using this row are provisional.
A26: Aon | B26: Current Ratio | C26: =IFERROR(C24/C25,"") -> 0.92763158 | D26: =IFERROR(D24/D25,"") -> 0.93548387 | E26: =IFERROR(E24/E25,"") -> 0.93209877 | F26: =IFERROR(F24/F25,"") -> 0.95757576 | G26: =IFERROR(G24/G25,"") -> 0.95266272 | H26: =IFERROR(H24/H25,"") -> 0.96491228 | I26: Calculated | J26: Calculated — inputs require review | K26: Formula is live; output reliability depends on source inputs. See Audit_Log for source status.
A27: Aon | B27: Total Debt | C27: 11.2 | D27: 11.5 | E27: 11.8 | F27: 12.1 | G27: 14.5 | H27: 15.87 | I27: https://www.sec.gov/Archives/edgar/data/315293/000162828026008116/aon-20251231.htm | J27: Needs review | K27: Not independently reconciled to the corresponding balance-sheet line items in this pass. Ratios using this row are provisional.
A28: Aon | B28: Interest Expense | C28: 0.42 | D28: 0.45 | E28: 0.48 | F28: 0.788 | G28: 0.815 | H28: 0.52 | I28: https://www.sec.gov/Archives/edgar/data/315293/000162828026008116/aon-20251231.htm | J28: Partially verified | K28: FY2023–FY2025 verified only where updated; any blank/unchanged year, 2021–2022, and 2026_TTM require source-line review. Definitions can differ across issuers.
A29: Aon | B29: Interest Coverage Ratio | C29: =IFERROR(C18/C28,"") -> 7.3809524 | D29: =IFERROR(D18/D28,"") -> 7.1111111 | E29: =IFERROR(E18/E28,"") -> 7.8854167 | F29: =IFERROR(F18/F28,"") -> 4.8667513 | G29: =IFERROR(G18/G28,"") -> 5.3300613 | H29: =IFERROR(H18/H28,"") -> 8.0769231 | I29: Calculated | J29: Calculated — inputs require review | K29: Formula is live; output reliability depends on source inputs. See Audit_Log for source status.
A30: MMC | B30: Total Revenue | C30: 19.82 | D30: 20.7 | E30: 22.736 | F30: 24.458 | G30: 26.981 | H30: 27.95 | I30: https://www.sec.gov/Archives/edgar/data/62709/000006270926000022/mrsh-20251231.htm | J30: Partially verified — FY2023–FY2025 | K30: FY2023–FY2025 values reconciled to cited FY2025 Form 10-K. 2021–2022 and 2026_TTM are not verified in this pass; see Audit_Log.
A31: MMC | B31: Revenue Growth YoY | C31: n/a | D31: =IFERROR(D30/C30-1,"") -> 0.044399596 | E31: =IFERROR(E30/D30-1,"") -> 0.098357488 | F31: =IFERROR(F30/E30-1,"") -> 0.075738916 | G31: =IFERROR(G30/F30-1,"") -> 0.10315643 | H31: n/a — TTM comparator unavailable | I31: Calculated | J31: Calculated (FY only) | K31: FY2024 and FY2025 growth use the reconciled FY2023–FY2025 revenue series. FY2023 growth still depends on the unverified FY2022 input. 2026_TTM growth is intentionally n/a because no prior comparable TTM period is provided.
A32: MMC | B32: Operating Income (EBIT) | C32: 4.3 | D32: 4.6 | E32: 5.282 | F32: 5.817 | G32: 6.223 | H32: 6.4 | I32: https://www.sec.gov/Archives/edgar/data/62709/000006270926000022/mrsh-20251231.htm | J32: Partially verified — FY2023–FY2025 | K32: FY2023–FY2025 values reconciled to cited FY2025 Form 10-K. 2021–2022 and 2026_TTM are not verified in this pass; see Audit_Log.
A33: MMC | B33: Net Income | C33: 3.1 | D33: 3.4 | E33: 3.756 | F33: 4.06 | G33: 4.16 | H33: 4.8 | I33: https://www.sec.gov/Archives/edgar/data/62709/000006270926000022/mrsh-20251231.htm | J33: Partially verified — FY2023–FY2025 | K33: FY2023–FY2025 values reconciled to cited FY2025 Form 10-K. 2021–2022 and 2026_TTM are not verified in this pass; see Audit_Log.
A34: MMC | B34: Net Profit Margin | C34: =IFERROR(C33/C30,"") -> 0.15640767 | D34: =IFERROR(D33/D30,"") -> 0.16425121 | E34: =IFERROR(E33/E30,"") -> 0.16520056 | F34: =IFERROR(F33/F30,"") -> 0.16599886 | G34: =IFERROR(G33/G30,"") -> 0.15418257 | H34: =IFERROR(H33/H30,"") -> 0.17173524 | I34: Calculated | J34: Calculated — inputs require review | K34: Formula is live; output reliability depends on source inputs. See Audit_Log for source status.
A35: MMC | B35: Operating Cash Flow | C35: 3.9 | D35: 4.2 | E35: 4.6 | F35: 4.9 | G35: 5.3 | H35: 5.8 | I35: https://www.sec.gov/Archives/edgar/data/62709/000006270926000022/mrsh-20251231.htm | J35: Needs review | K35: Historical and TTM values have not all been reconciled to the cash-flow statement; do not treat as confirmed.
A36: MMC | B36: Capital Expenditures | C36: 0.5 | D36: 0.55 | E36: 0.6 | F36: 0.65 | G36: 0.7 | H36: 0.78 | I36: https://www.sec.gov/Archives/edgar/data/62709/000006270926000022/mrsh-20251231.htm | J36: Needs review | K36: Historical and TTM values have not all been reconciled to the cash-flow statement; do not treat as confirmed.
A37: MMC | B37: Free Cash Flow | C37: =IFERROR(C35-C36,"") -> 3.4 | D37: =IFERROR(D35-D36,"") -> 3.65 | E37: =IFERROR(E35-E36,"") -> 4 | F37: =IFERROR(F35-F36,"") -> 4.25 | G37: =IFERROR(G35-G36,"") -> 4.6 | H37: =IFERROR(H35-H36,"") -> 5.02 | I37: Calculated | J37: Calculated — inputs require review | K37: Formula is live; output reliability depends on source inputs. See Audit_Log for source status.
A38: MMC | B38: Current Assets | C38: 22.1 | D38: 23.4 | E38: 24.8 | F38: 26.1 | G38: 27.5 | H38: 28.9 | I38: https://www.sec.gov/Archives/edgar/data/62709/000006270926000022/mrsh-20251231.htm | J38: Needs review | K38: Not independently reconciled to the corresponding balance-sheet line items in this pass. Ratios using this row are provisional.
A39: MMC | B39: Current Liabilities | C39: 19.5 | D39: 20.1 | E39: 21.3 | F39: 22.4 | G39: 23.1 | H39: 24.2 | I39: https://www.sec.gov/Archives/edgar/data/62709/000006270926000022/mrsh-20251231.htm | J39: Needs review | K39: Not independently reconciled to the corresponding balance-sheet line items in this pass. Ratios using this row are provisional.
A40: MMC | B40: Current Ratio | C40: =IFERROR(C38/C39,"") -> 1.1333333 | D40: =IFERROR(D38/D39,"") -> 1.1641791 | E40: =IFERROR(E38/E39,"") -> 1.1643192 | F40: =IFERROR(F38/F39,"") -> 1.1651786 | G40: =IFERROR(G38/G39,"") -> 1.1904762 | H40: =IFERROR(H38/H39,"") -> 1.1942149 | I40: Calculated | J40: Calculated — inputs require review | K40: Formula is live; output reliability depends on source inputs. See Audit_Log for source status.
...

Sheet Stress_Test_Matrix
A1: Company | B1: Scenario | C1: Revenue Shock | D1: Stressed Revenue (USD bn) | E1: Stressed EBIT (USD bn) | F1: Stressed Interest Coverage (x) | G1: Illustrative Coverage Assessment | H1: DOL Assumption | I1: Formula / Scenario Meaning | J1: Baseline Period / Caveat | K1: Method Note | M1: Assumptions (inputs) | N1: Value
A2: WTW | B2: Base Case | C2: 0 | D2: =Financial_Metrics!G2*(1+C2) -> 9.708 | E2: =Financial_Metrics!G4*(1+H2*C2) -> 2.234 | F2: =IFERROR(E2/Financial_Metrics!G14,"") -> 8.5923077 | G2: =IF(F2="","Not assessed",IF(F2>=$N$3,"Illustrative buffer",IF(F2>=$N$4,"Pressure","High pressure"))) -> Illustrative buffer | H2: =$N$2 -> 2.5 | I2: Revenue = FY2025 revenue × (1 + shock); EBIT proxy = FY2025 EBIT × (1 + DOL × shock). | J2: FY2025 baseline; sensitivity analysis only, not a forecast. | K2: DOL = 2.5 is an explicit assumption. Coverage thresholds are illustrative, not validated credit ratings. | M2: DOL (degree of operating leverage) | N2: 2.5
A3: WTW | B3: Mild Stress | C3: -0.05 | D3: =Financial_Metrics!G2*(1+C3) -> 9.2226 | E3: =Financial_Metrics!G4*(1+H3*C3) -> 1.95475 | F3: =IFERROR(E3/Financial_Metrics!G14,"") -> 7.5182692 | G3: =IF(F3="","Not assessed",IF(F3>=$N$3,"Illustrative buffer",IF(F3>=$N$4,"Pressure","High pressure"))) -> Illustrative buffer | H3: =$N$2 -> 2.5 | I3: Revenue = FY2025 revenue × (1 + shock); EBIT proxy = FY2025 EBIT × (1 + DOL × shock). | J3: FY2025 baseline; sensitivity analysis only, not a forecast. | K3: DOL = 2.5 is an explicit assumption. Coverage thresholds are illustrative, not validated credit ratings. | M3: "Illustrative buffer" threshold (x) | N3: 5
A4: WTW | B4: Severe Stress | C4: -0.1 | D4: =Financial_Metrics!G2*(1+C4) -> 8.7372 | E4: =Financial_Metrics!G4*(1+H4*C4) -> 1.6755 | F4: =IFERROR(E4/Financial_Metrics!G14,"") -> 6.4442308 | G4: =IF(F4="","Not assessed",IF(F4>=$N$3,"Illustrative buffer",IF(F4>=$N$4,"Pressure","High pressure"))) -> Illustrative buffer | H4: =$N$2 -> 2.5 | I4: Revenue = FY2025 revenue × (1 + shock); EBIT proxy = FY2025 EBIT × (1 + DOL × shock). | J4: FY2025 baseline; sensitivity analysis only, not a forecast. | K4: DOL = 2.5 is an explicit assumption. Coverage thresholds are illustrative, not validated credit ratings. | M4: "Pressure" threshold (x) | N4: 2
A5: WTW | B5: Critical Shock | C5: -0.25 | D5: =Financial_Metrics!G2*(1+C5) -> 7.281 | E5: =Financial_Metrics!G4*(1+H5*C5) -> 0.83775 | F5: =IFERROR(E5/Financial_Metrics!G14,"") -> 3.2221154 | G5: =IF(F5="","Not assessed",IF(F5>=$N$3,"Illustrative buffer",IF(F5>=$N$4,"Pressure","High pressure"))) -> Pressure | H5: =$N$2 -> 2.5 | I5: Revenue = FY2025 revenue × (1 + shock); EBIT proxy = FY2025 EBIT × (1 + DOL × shock). | J5: FY2025 baseline; sensitivity analysis only, not a forecast. | K5: DOL = 2.5 is an explicit assumption. Coverage thresholds are illustrative, not validated credit ratings.
A6: Aon | B6: Base Case | C6: 0 | D6: =Financial_Metrics!G16*(1+C6) -> 17.181 | E6: =Financial_Metrics!G18*(1+H6*C6) -> 4.344 | F6: =IFERROR(E6/Financial_Metrics!G28,"") -> 5.3300613 | G6: =IF(F6="","Not assessed",IF(F6>=$N$3,"Illustrative buffer",IF(F6>=$N$4,"Pressure","High pressure"))) -> Illustrative buffer | H6: =$N$2 -> 2.5 | I6: Revenue = FY2025 revenue × (1 + shock); EBIT proxy = FY2025 EBIT × (1 + DOL × shock). | J6: FY2025 baseline; sensitivity analysis only, not a forecast. | K6: DOL = 2.5 is an explicit assumption. Coverage thresholds are illustrative, not validated credit ratings.
A7: Aon | B7: Mild Stress | C7: -0.05 | D7: =Financial_Metrics!G16*(1+C7) -> 16.32195 | E7: =Financial_Metrics!G18*(1+H7*C7) -> 3.801 | F7: =IFERROR(E7/Financial_Metrics!G28,"") -> 4.6638037 | G7: =IF(F7="","Not assessed",IF(F7>=$N$3,"Illustrative buffer",IF(F7>=$N$4,"Pressure","High pressure"))) -> Pressure | H7: =$N$2 -> 2.5 | I7: Revenue = FY2025 revenue × (1 + shock); EBIT proxy = FY2025 EBIT × (1 + DOL × shock). | J7: FY2025 baseline; sensitivity analysis only, not a forecast. | K7: DOL = 2.5 is an explicit assumption. Coverage thresholds are illustrative, not validated credit ratings.
A8: Aon | B8: Severe Stress | C8: -0.1 | D8: =Financial_Metrics!G16*(1+C8) -> 15.4629 | E8: =Financial_Metrics!G18*(1+H8*C8) -> 3.258 | F8: =IFERROR(E8/Financial_Metrics!G28,"") -> 3.997546 | G8: =IF(F8="","Not assessed",IF(F8>=$N$3,"Illustrative buffer",IF(F8>=$N$4,"Pressure","High pressure"))) -> Pressure | H8: =$N$2 -> 2.5 | I8: Revenue = FY2025 revenue × (1 + shock); EBIT proxy = FY2025 EBIT × (1 + DOL × shock). | J8: FY2025 baseline; sensitivity analysis only, not a forecast. | K8: DOL = 2.5 is an explicit assumption. Coverage thresholds are illustrative, not validated credit ratings.
A9: Aon | B9: Critical Shock | C9: -0.25 | D9: =Financial_Metrics!G16*(1+C9) -> 12.88575 | E9: =Financial_Metrics!G18*(1+H9*C9) -> 1.629 | F9: =IFERROR(E9/Financial_Metrics!G28,"") -> 1.998773 | G9: =IF(F9="","Not assessed",IF(F9>=$N$3,"Illustrative buffer",IF(F9>=$N$4,"Pressure","High pressure"))) -> High pressure | H9: =$N$2 -> 2.5 | I9: Revenue = FY2025 revenue × (1 + shock); EBIT proxy = FY2025 EBIT × (1 + DOL × shock). | J9: FY2025 baseline; sensitivity analysis only, not a forecast. | K9: DOL = 2.5 is an explicit assumption. Coverage thresholds are illustrative, not validated credit ratings.
A10: MMC | B10: Base Case | C10: 0 | D10: =Financial_Metrics!G30*(1+C10) -> 26.981 | E10: =Financial_Metrics!G32*(1+H10*C10) -> 6.223 | F10: =IFERROR(E10/Financial_Metrics!G42,"") -> 6.4822917 | G10: =IF(F10="","Not assessed",IF(F10>=$N$3,"Illustrative buffer",IF(F10>=$N$4,"Pressure","High pressure"))) -> Illustrative buffer | H10: =$N$2 -> 2.5 | I10: Revenue = FY2025 revenue × (1 + shock); EBIT proxy = FY2025 EBIT × (1 + DOL × shock). | J10: FY2025 baseline; sensitivity analysis only, not a forecast. | K10: DOL = 2.5 is an explicit assumption. Coverage thresholds are illustrative, not validated credit ratings.
A11: MMC | B11: Mild Stress | C11: -0.05 | D11: =Financial_Metrics!G30*(1+C11) -> 25.63195 | E11: =Financial_Metrics!G32*(1+H11*C11) -> 5.445125 | F11: =IFERROR(E11/Financial_Metrics!G42,"") -> 5.6720052 | G11: =IF(F11="","Not assessed",IF(F11>=$N$3,"Illustrative buffer",IF(F11>=$N$4,"Pressure","High pressure"))) -> Illustrative buffer | H11: =$N$2 -> 2.5 | I11: Revenue = FY2025 revenue × (1 + shock); EBIT proxy = FY2025 EBIT × (1 + DOL × shock). | J11: FY2025 baseline; sensitivity analysis only, not a forecast. | K11: DOL = 2.5 is an explicit assumption. Coverage thresholds are illustrative, not validated credit ratings.
A12: MMC | B12: Severe Stress | C12: -0.1 | D12: =Financial_Metrics!G30*(1+C12) -> 24.2829 | E12: =Financial_Metrics!G32*(1+H12*C12) -> 4.66725 | F12: =IFERROR(E12/Financial_Metrics!G42,"") -> 4.8617187 | G12: =IF(F12="","Not assessed",IF(F12>=$N$3,"Illustrative buffer",IF(F12>=$N$4,"Pressure","High pressure"))) -> Pressure | H12: =$N$2 -> 2.5 | I12: Revenue = FY2025 revenue × (1 + shock); EBIT proxy = FY2025 EBIT × (1 + DOL × shock). | J12: FY2025 baseline; sensitivity analysis only, not a forecast. | K12: DOL = 2.5 is an explicit assumption. Coverage thresholds are illustrative, not validated credit ratings.
A13: MMC | B13: Critical Shock | C13: -0.25 | D13: =Financial_Metrics!G30*(1+C13) -> 20.23575 | E13: =Financial_Metrics!G32*(1+H13*C13) -> 2.333625 | F13: =IFERROR(E13/Financial_Metrics!G42,"") -> 2.4308594 | G13: =IF(F13="","Not assessed",IF(F13>=$N$3,"Illustrative buffer",IF(F13>=$N$4,"Pressure","High pressure"))) -> Pressure | H13: =$N$2 -> 2.5 | I13: Revenue = FY2025 revenue × (1 + shock); EBIT proxy = FY2025 EBIT × (1 + DOL × shock). | J13: FY2025 baseline; sensitivity analysis only, not a forecast. | K13: DOL = 2.5 is an explicit assumption. Coverage thresholds are illustrative, not validated credit ratings.
A14: AJG | B14: Base Case | C14: 0 | D14: =Financial_Metrics!G44*(1+C14) -> 13.942 | E14: =Financial_Metrics!G46*(1+H14*C14) -> 2.51 | F14: =IFERROR(E14/Financial_Metrics!G56,"") -> 3.9280125 | G14: =IF(F14="","Not assessed",IF(F14>=$N$3,"Illustrative buffer",IF(F14>=$N$4,"Pressure","High pressure"))) -> Pressure | H14: =$N$2 -> 2.5 | I14: Revenue = FY2025 revenue × (1 + shock); EBIT proxy = FY2025 EBIT × (1 + DOL × shock). | J14: FY2025 baseline; sensitivity analysis only, not a forecast. | K14: DOL = 2.5 is an explicit assumption. Coverage thresholds are illustrative, not validated credit ratings.
A15: AJG | B15: Mild Stress | C15: -0.05 | D15: =Financial_Metrics!G44*(1+C15) -> 13.2449 | E15: =Financial_Metrics!G46*(1+H15*C15) -> 2.19625 | F15: =IFERROR(E15/Financial_Metrics!G56,"") -> 3.437011 | G15: =IF(F15="","Not assessed",IF(F15>=$N$3,"Illustrative buffer",IF(F15>=$N$4,"Pressure","High pressure"))) -> Pressure | H15: =$N$2 -> 2.5 | I15: Revenue = FY2025 revenue × (1 + shock); EBIT proxy = FY2025 EBIT × (1 + DOL × shock). | J15: FY2025 baseline; sensitivity analysis only, not a forecast. | K15: DOL = 2.5 is an explicit assumption. Coverage thresholds are illustrative, not validated credit ratings.
A16: AJG | B16: Severe Stress | C16: -0.1 | D16: =Financial_Metrics!G44*(1+C16) -> 12.5478 | E16: =Financial_Metrics!G46*(1+H16*C16) -> 1.8825 | F16: =IFERROR(E16/Financial_Metrics!G56,"") -> 2.9460094 | G16: =IF(F16="","Not assessed",IF(F16>=$N$3,"Illustrative buffer",IF(F16>=$N$4,"Pressure","High pressure"))) -> Pressure | H16: =$N$2 -> 2.5 | I16: Revenue = FY2025 revenue × (1 + shock); EBIT proxy = FY2025 EBIT × (1 + DOL × shock). | J16: FY2025 baseline; sensitivity analysis only, not a forecast. | K16: DOL = 2.5 is an explicit assumption. Coverage thresholds are illustrative, not validated credit ratings.
A17: AJG | B17: Critical Shock | C17: -0.25 | D17: =Financial_Metrics!G44*(1+C17) -> 10.4565 | E17: =Financial_Metrics!G46*(1+H17*C17) -> 0.94125 | F17: =IFERROR(E17/Financial_Metrics!G56,"") -> 1.4730047 | G17: =IF(F17="","Not assessed",IF(F17>=$N$3,"Illustrative buffer",IF(F17>=$N$4,"Pressure","High pressure"))) -> High pressure | H17: =$N$2 -> 2.5 | I17: Revenue = FY2025 revenue × (1 + shock); EBIT proxy = FY2025 EBIT × (1 + DOL × shock). | J17: FY2025 baseline; sensitivity analysis only, not a forecast. | K17: DOL = 2.5 is an explicit assumption. Coverage thresholds are illustrative, not validated credit ratings.
A18: BRO | B18: Base Case | C18: 0 | D18: =Financial_Metrics!G58*(1+C18) -> 5.902 | E18: =Financial_Metrics!G60*(1+H18*C18) -> 1.668 | F18: =IFERROR(E18/Financial_Metrics!G70,"") -> 5.6161616 | G18: =IF(F18="","Not assessed",IF(F18>=$N$3,"Illustrative buffer",IF(F18>=$N$4,"Pressure","High pressure"))) -> Illustrative buffer | H18: =$N$2 -> 2.5 | I18: Revenue = FY2025 revenue × (1 + shock); EBIT proxy = FY2025 EBIT × (1 + DOL × shock). | J18: FY2025 baseline; sensitivity analysis only, not a forecast. | K18: DOL = 2.5 is an explicit assumption. Coverage thresholds are illustrative, not validated credit ratings.
A19: BRO | B19: Mild Stress | C19: -0.05 | D19: =Financial_Metrics!G58*(1+C19) -> 5.6069 | E19: =Financial_Metrics!G60*(1+H19*C19) -> 1.4595 | F19: =IFERROR(E19/Financial_Metrics!G70,"") -> 4.9141414 | G19: =IF(F19="","Not assessed",IF(F19>=$N$3,"Illustrative buffer",IF(F19>=$N$4,"Pressure","High pressure"))) -> Pressure | H19: =$N$2 -> 2.5 | I19: Revenue = FY2025 revenue × (1 + shock); EBIT proxy = FY2025 EBIT × (1 + DOL × shock). | J19: FY2025 baseline; sensitivity analysis only, not a forecast. | K19: DOL = 2.5 is an explicit assumption. Coverage thresholds are illustrative, not validated credit ratings.
A20: BRO | B20: Severe Stress | C20: -0.1 | D20: =Financial_Metrics!G58*(1+C20) -> 5.3118 | E20: =Financial_Metrics!G60*(1+H20*C20) -> 1.251 | F20: =IFERROR(E20/Financial_Metrics!G70,"") -> 4.2121212 | G20: =IF(F20="","Not assessed",IF(F20>=$N$3,"Illustrative buffer",IF(F20>=$N$4,"Pressure","High pressure"))) -> Pressure | H20: =$N$2 -> 2.5 | I20: Revenue = FY2025 revenue × (1 + shock); EBIT proxy = FY2025 EBIT × (1 + DOL × shock). | J20: FY2025 baseline; sensitivity analysis only, not a forecast. | K20: DOL = 2.5 is an explicit assumption. Coverage thresholds are illustrative, not validated credit ratings.
A21: BRO | B21: Critical Shock | C21: -0.25 | D21: =Financial_Metrics!G58*(1+C21) -> 4.4265 | E21: =Financial_Metrics!G60*(1+H21*C21) -> 0.6255 | F21: =IFERROR(E21/Financial_Metrics!G70,"") -> 2.1060606 | G21: =IF(F21="","Not assessed",IF(F21>=$N$3,"Illustrative buffer",IF(F21>=$N$4,"Pressure","High pressure"))) -> Pressure | H21: =$N$2 -> 2.5 | I21: Revenue = FY2025 revenue × (1 + shock); EBIT proxy = FY2025 EBIT × (1 + DOL × shock). | J21: FY2025 baseline; sensitivity analysis only, not a forecast. | K21: DOL = 2.5 is an explicit assumption. Coverage thresholds are illustrative, not validated credit ratings.

Sheet Financial_Ratios
A1: Company | B1: Period | C1: Current Ratio | D1: Interest Coverage Ratio | E1: Debt-to-Equity | F1: Debt-to-EBITDA | G1: Free Cash Flow Margin | H1: Operating Cash Flow / Total Debt | I1: Formula / Interpretation | J1: Limitations / Status | K1: Operating Profit Margin (EBIT / Revenue)
A2: WTW | B2: 2021 | C2: =IFERROR(Financial_Metrics!C10/Financial_Metrics!C11,"") -> 1.0714286 | D2: =IFERROR(Financial_Metrics!C4/Financial_Metrics!C14,"") -> 6.25 | E2: N/A — equity data unavailable | F2: N/A — EBITDA inputs unavailable | G2: =IFERROR(Financial_Metrics!C9/Financial_Metrics!C2,"") -> 0.20333333 | H2: =IFERROR(Financial_Metrics!C7/Financial_Metrics!C13,"") -> 0.38433515 | I2: Current ratio = current assets / current liabilities; coverage = EBIT / interest expense; FCF margin = FCF / revenue; OCF/debt = operating cash flow / total debt. | J2: Provisional: formula-driven, but source inputs for balance-sheet and cash-flow ratios still need reconciliation. Debt-to-Equity and Debt-to-EBITDA unavailable. | K2: =IFERROR(Financial_Metrics!C4/Financial_Metrics!C2,"") -> 0.19444444
A3: WTW | B3: 2022 | C3: =IFERROR(Financial_Metrics!D10/Financial_Metrics!D11,"") -> 1.0696056 | D3: =IFERROR(Financial_Metrics!D4/Financial_Metrics!D14,"") -> 6.0333333 | E3: N/A — equity data unavailable | F3: N/A — EBITDA inputs unavailable | G3: =IFERROR(Financial_Metrics!D9/Financial_Metrics!D2,"") -> 0.075535513 | H3: =IFERROR(Financial_Metrics!D7/Financial_Metrics!D13,"") -> 0.1770073 | I3: Current ratio = current assets / current liabilities; coverage = EBIT / interest expense; FCF margin = FCF / revenue; OCF/debt = operating cash flow / total debt. | J3: Provisional: formula-driven, but source inputs for balance-sheet and cash-flow ratios still need reconciliation. Debt-to-Equity and Debt-to-EBITDA unavailable. | K3: =IFERROR(Financial_Metrics!D4/Financial_Metrics!D2,"") -> 0.20405862
A4: WTW | B4: 2023 | C4: =IFERROR(Financial_Metrics!E10/Financial_Metrics!E11,"") -> 1.0603318 | D4: =IFERROR(Financial_Metrics!E4/Financial_Metrics!E14,"") -> 5.8085106 | E4: N/A — equity data unavailable | F4: N/A — EBITDA inputs unavailable | G4: =IFERROR(Financial_Metrics!E9/Financial_Metrics!E2,"") -> 0.1163134 | H4: =IFERROR(Financial_Metrics!E7/Financial_Metrics!E13,"") -> 0.22605042 | I4: Current ratio = current assets / current liabilities; coverage = EBIT / interest expense; FCF margin = FCF / revenue; OCF/debt = operating cash flow / total debt. | J4: Provisional: formula-driven, but source inputs for balance-sheet and cash-flow ratios still need reconciliation. Debt-to-Equity and Debt-to-EBITDA unavailable. | K4: =IFERROR(Financial_Metrics!E4/Financial_Metrics!E2,"") -> 0.14394179
A5: WTW | B5: 2024 | C5: =IFERROR(Financial_Metrics!F10/Financial_Metrics!F11,"") -> 1.1989998 | D5: =IFERROR(Financial_Metrics!F4/Financial_Metrics!F14,"") -> 2.3840304 | E5: N/A — equity data unavailable | F5: N/A — EBITDA inputs unavailable | G5: =IFERROR(Financial_Metrics!F9/Financial_Metrics!F2,"") -> 0.12759315 | H5: =IFERROR(Financial_Metrics!F7/Financial_Metrics!F13,"") -> 0.25501771 | I5: Current ratio = current assets / current liabilities; coverage = EBIT / interest expense; FCF margin = FCF / revenue; OCF/debt = operating cash flow / total debt. | J5: Provisional: formula-driven, but source inputs for balance-sheet and cash-flow ratios still need reconciliation. Debt-to-Equity and Debt-to-EBITDA unavailable. | K5: =IFERROR(Financial_Metrics!F4/Financial_Metrics!F2,"") -> 0.063141994
A6: WTW | B6: 2025 | C6: =IFERROR(Financial_Metrics!G10/Financial_Metrics!G11,"") -> 1.2049414 | D6: =IFERROR(Financial_Metrics!G4/Financial_Metrics!G14,"") -> 8.5923077 | E6: N/A — equity data unavailable | F6: N/A — EBITDA inputs unavailable | G6: =IFERROR(Financial_Metrics!G9/Financial_Metrics!G2,"") -> 0.1592501 | H6: =IFERROR(Financial_Metrics!G7/Financial_Metrics!G13,"") -> 0.25713458 | I6: Current ratio = current assets / current liabilities; coverage = EBIT / interest expense; FCF margin = FCF / revenue; OCF/debt = operating cash flow / total debt. | J6: Provisional: formula-driven, but source inputs for balance-sheet and cash-flow ratios still need reconciliation. Debt-to-Equity and Debt-to-EBITDA unavailable. | K6: =IFERROR(Financial_Metrics!G4/Financial_Metrics!G2,"") -> 0.23011949
A7: WTW | B7: 2026_TTM | C7: =IFERROR(Financial_Metrics!H10/Financial_Metrics!H11,"") -> 1.0983607 | D7: =IFERROR(Financial_Metrics!H4/Financial_Metrics!H14,"") -> 5.2058824 | E7: N/A — equity data unavailable | F7: N/A — EBITDA inputs unavailable | G7: =IFERROR(Financial_Metrics!H9/Financial_Metrics!H2,"") -> 0.16732673 | H7: =IFERROR(Financial_Metrics!H7/Financial_Metrics!H13,"") -> 0.28732394 | I7: Current ratio = current assets / current liabilities; coverage = EBIT / interest expense; FCF margin = FCF / revenue; OCF/debt = operating cash flow / total debt. | J7: Provisional: formula-driven, but source inputs for balance-sheet and cash-flow ratios still need reconciliation. Debt-to-Equity and Debt-to-EBITDA unavailable. | K7: =IFERROR(Financial_Metrics!H4/Financial_Metrics!H2,"") -> 0.17524752
A8: Aon | B8: 2021 | C8: =IFERROR(Financial_Metrics!C24/Financial_Metrics!C25,"") -> 0.92763158 | D8: =IFERROR(Financial_Metrics!C18/Financial_Metrics!C28,"") -> 7.3809524 | E8: N/A — equity data unavailable | F8: N/A — EBITDA inputs unavailable | G8: =IFERROR(Financial_Metrics!C23/Financial_Metrics!C16,"") -> 0.18032787 | H8: =IFERROR(Financial_Metrics!C21/Financial_Metrics!C27,"") -> 0.23214286 | I8: Current ratio = current assets / current liabilities; coverage = EBIT / interest expense; FCF margin = FCF / revenue; OCF/debt = operating cash flow / total debt. | J8: Provisional: formula-driven, but source inputs for balance-sheet and cash-flow ratios still need reconciliation. Debt-to-Equity and Debt-to-EBITDA unavailable. | K8: =IFERROR(Financial_Metrics!C18/Financial_Metrics!C16,"") -> 0.25409836
A9: Aon | B9: 2022 | C9: =IFERROR(Financial_Metrics!D24/Financial_Metrics!D25,"") -> 0.93548387 | D9: =IFERROR(Financial_Metrics!D18/Financial_Metrics!D28,"") -> 7.1111111 | E9: N/A — equity data unavailable | F9: N/A — EBITDA inputs unavailable | G9: =IFERROR(Financial_Metrics!D23/Financial_Metrics!D16,"") -> 0.188 | H9: =IFERROR(Financial_Metrics!D21/Financial_Metrics!D27,"") -> 0.24347826 | I9: Current ratio = current assets / current liabilities; coverage = EBIT / interest expense; FCF margin = FCF / revenue; OCF/debt = operating cash flow / total debt. | J9: Provisional: formula-driven, but source inputs for balance-sheet and cash-flow ratios still need reconciliation. Debt-to-Equity and Debt-to-EBITDA unavailable. | K9: =IFERROR(Financial_Metrics!D18/Financial_Metrics!D16,"") -> 0.256
A10: Aon | B10: 2023 | C10: =IFERROR(Financial_Metrics!E24/Financial_Metrics!E25,"") -> 0.93209877 | D10: =IFERROR(Financial_Metrics!E18/Financial_Metrics!E28,"") -> 7.8854167 | E10: N/A — equity data unavailable | F10: N/A — EBITDA inputs unavailable | G10: =IFERROR(Financial_Metrics!E23/Financial_Metrics!E16,"") -> 0.19437799 | H10: =IFERROR(Financial_Metrics!E21/Financial_Metrics!E27,"") -> 0.26271186 | I10: Current ratio = current assets / current liabilities; coverage = EBIT / interest expense; FCF margin = FCF / revenue; OCF/debt = operating cash flow / total debt. | J10: Provisional: formula-driven, but source inputs for balance-sheet and cash-flow ratios still need reconciliation. Debt-to-Equity and Debt-to-EBITDA unavailable. | K10: =IFERROR(Financial_Metrics!E18/Financial_Metrics!E16,"") -> 0.2829695
A11: Aon | B11: 2024 | C11: =IFERROR(Financial_Metrics!F24/Financial_Metrics!F25,"") -> 0.95757576 | D11: =IFERROR(Financial_Metrics!F18/Financial_Metrics!F28,"") -> 4.8667513 | E11: N/A — equity data unavailable | F11: N/A — EBITDA inputs unavailable | G11: =IFERROR(Financial_Metrics!F23/Financial_Metrics!F16,"") -> 0.16881131 | H11: =IFERROR(Financial_Metrics!F21/Financial_Metrics!F27,"") -> 0.26446281 | I11: Current ratio = current assets / current liabilities; coverage = EBIT / interest expense; FCF margin = FCF / revenue; OCF/debt = operating cash flow / total debt. | J11: Provisional: formula-driven, but source inputs for balance-sheet and cash-flow ratios still need reconciliation. Debt-to-Equity and Debt-to-EBITDA unavailable. | K11: =IFERROR(Financial_Metrics!F18/Financial_Metrics!F16,"") -> 0.24429864
A12: Aon | B12: 2025 | C12: =IFERROR(Financial_Metrics!G24/Financial_Metrics!G25,"") -> 0.95266272 | D12: =IFERROR(Financial_Metrics!G18/Financial_Metrics!G28,"") -> 5.3300613 | E12: N/A — equity data unavailable | F12: N/A — EBITDA inputs unavailable | G12: =IFERROR(Financial_Metrics!G23/Financial_Metrics!G16,"") -> 0.16588091 | H12: =IFERROR(Financial_Metrics!G21/Financial_Metrics!G27,"") -> 0.24137931 | I12: Current ratio = current assets / current liabilities; coverage = EBIT / interest expense; FCF margin = FCF / revenue; OCF/debt = operating cash flow / total debt. | J12: Provisional: formula-driven, but source inputs for balance-sheet and cash-flow ratios still need reconciliation. Debt-to-Equity and Debt-to-EBITDA unavailable. | K12: =IFERROR(Financial_Metrics!G18/Financial_Metrics!G16,"") -> 0.25283744
A13: Aon | B13: 2026_TTM | C13: =IFERROR(Financial_Metrics!H24/Financial_Metrics!H25,"") -> 0.96491228 | D13: =IFERROR(Financial_Metrics!H18/Financial_Metrics!H28,"") -> 8.0769231 | E13: N/A — equity data unavailable | F13: N/A — EBITDA inputs unavailable | G13: =IFERROR(Financial_Metrics!H23/Financial_Metrics!H16,"") -> 0.17463026 | H13: =IFERROR(Financial_Metrics!H21/Financial_Metrics!H27,"") -> 0.23944549 | I13: Current ratio = current assets / current liabilities; coverage = EBIT / interest expense; FCF margin = FCF / revenue; OCF/debt = operating cash flow / total debt. | J13: Provisional: formula-driven, but source inputs for balance-sheet and cash-flow ratios still need reconciliation. Debt-to-Equity and Debt-to-EBITDA unavailable. | K13: =IFERROR(Financial_Metrics!H18/Financial_Metrics!H16,"") -> 0.23890785
A14: MMC | B14: 2021 | C14: =IFERROR(Financial_Metrics!C38/Financial_Metrics!C39,"") -> 1.1333333 | D14: =IFERROR(Financial_Metrics!C32/Financial_Metrics!C42,"") -> 8.6 | E14: N/A — equity data unavailable | F14: N/A — EBITDA inputs unavailable | G14: =IFERROR(Financial_Metrics!C37/Financial_Metrics!C30,"") -> 0.1715439 | H14: =IFERROR(Financial_Metrics!C35/Financial_Metrics!C41,"") -> 0.34210526 | I14: Current ratio = current assets / current liabilities; coverage = EBIT / interest expense; FCF margin = FCF / revenue; OCF/debt = operating cash flow / total debt. | J14: Provisional: formula-driven, but source inputs for balance-sheet and cash-flow ratios still need reconciliation. Debt-to-Equity and Debt-to-EBITDA unavailable. | K14: =IFERROR(Financial_Metrics!C32/Financial_Metrics!C30,"") -> 0.21695257
A15: MMC | B15: 2022 | C15: =IFERROR(Financial_Metrics!D38/Financial_Metrics!D39,"") -> 1.1641791 | D15: =IFERROR(Financial_Metrics!D32/Financial_Metrics!D42,"") -> 8.8461538 | E15: N/A — equity data unavailable | F15: N/A — EBITDA inputs unavailable | G15: =IFERROR(Financial_Metrics!D37/Financial_Metrics!D30,"") -> 0.1763285 | H15: =IFERROR(Financial_Metrics!D35/Financial_Metrics!D41,"") -> 0.35294118 | I15: Current ratio = current assets / current liabilities; coverage = EBIT / interest expense; FCF margin = FCF / revenue; OCF/debt = operating cash flow / total debt. | J15: Provisional: formula-driven, but source inputs for balance-sheet and cash-flow ratios still need reconciliation. Debt-to-Equity and Debt-to-EBITDA unavailable. | K15: =IFERROR(Financial_Metrics!D32/Financial_Metrics!D30,"") -> 0.22222222
A16: MMC | B16: 2023 | C16: =IFERROR(Financial_Metrics!E38/Financial_Metrics!E39,"") -> 1.1643192 | D16: =IFERROR(Financial_Metrics!E32/Financial_Metrics!E42,"") -> 9.1384083 | E16: N/A — equity data unavailable | F16: N/A — EBITDA inputs unavailable | G16: =IFERROR(Financial_Metrics!E37/Financial_Metrics!E30,"") -> 0.17593244 | H16: =IFERROR(Financial_Metrics!E35/Financial_Metrics!E41,"") -> 0.37398374 | I16: Current ratio = current assets / current liabilities; coverage = EBIT / interest expense; FCF margin = FCF / revenue; OCF/debt = operating cash flow / total debt. | J16: Provisional: formula-driven, but source inputs for balance-sheet and cash-flow ratios still need reconciliation. Debt-to-Equity and Debt-to-EBITDA unavailable. | K16: =IFERROR(Financial_Metrics!E32/Financial_Metrics!E30,"") -> 0.23231879
A17: MMC | B17: 2024 | C17: =IFERROR(Financial_Metrics!F38/Financial_Metrics!F39,"") -> 1.1651786 | D17: =IFERROR(Financial_Metrics!F32/Financial_Metrics!F42,"") -> 8.31 | E17: N/A — equity data unavailable | F17: N/A — EBITDA inputs unavailable | G17: =IFERROR(Financial_Metrics!F37/Financial_Metrics!F30,"") -> 0.17376727 | H17: =IFERROR(Financial_Metrics!F35/Financial_Metrics!F41,"") -> 0.3828125 | I17: Current ratio = current assets / current liabilities; coverage = EBIT / interest expense; FCF margin = FCF / revenue; OCF/debt = operating cash flow / total debt. | J17: Provisional: formula-driven, but source inputs for balance-sheet and cash-flow ratios still need reconciliation. Debt-to-Equity and Debt-to-EBITDA unavailable. | K17: =IFERROR(Financial_Metrics!F32/Financial_Metrics!F30,"") -> 0.23783629
A18: MMC | B18: 2025 | C18: =IFERROR(Financial_Metrics!G38/Financial_Metrics!G39,"") -> 1.1904762 | D18: =IFERROR(Financial_Metrics!G32/Financial_Metrics!G42,"") -> 6.4822917 | E18: N/A — equity data unavailable | F18: N/A — EBITDA inputs unavailable | G18: =IFERROR(Financial_Metrics!G37/Financial_Metrics!G30,"") -> 0.17049035 | H18: =IFERROR(Financial_Metrics!G35/Financial_Metrics!G41,"") -> 0.39552239 | I18: Current ratio = current assets / current liabilities; coverage = EBIT / interest expense; FCF margin = FCF / revenue; OCF/debt = operating cash flow / total debt. | J18: Provisional: formula-driven, but source inputs for balance-sheet and cash-flow ratios still need reconciliation. Debt-to-Equity and Debt-to-EBITDA unavailable. | K18: =IFERROR(Financial_Metrics!G32/Financial_Metrics!G30,"") -> 0.23064379
A19: MMC | B19: 2026_TTM | C19: =IFERROR(Financial_Metrics!H38/Financial_Metrics!H39,"") -> 1.1942149 | D19: =IFERROR(Financial_Metrics!H32/Financial_Metrics!H42,"") -> 10.322581 | E19: N/A — equity data unavailable | F19: N/A — EBITDA inputs unavailable | G19: =IFERROR(Financial_Metrics!H37/Financial_Metrics!H30,"") -> 0.17960644 | H19: =IFERROR(Financial_Metrics!H35/Financial_Metrics!H41,"") -> 0.41134752 | I19: Current ratio = current assets / current liabilities; coverage = EBIT / interest expense; FCF margin = FCF / revenue; OCF/debt = operating cash flow / total debt. | J19: Provisional: formula-driven, but source inputs for balance-sheet and cash-flow ratios still need reconciliation. Debt-to-Equity and Debt-to-EBITDA unavailable. | K19: =IFERROR(Financial_Metrics!H32/Financial_Metrics!H30,"") -> 0.22898032
A20: AJG | B20: 2021 | C20: =IFERROR(Financial_Metrics!C52/Financial_Metrics!C53,"") -> 1.2 | D20: =IFERROR(Financial_Metrics!C46/Financial_Metrics!C56,"") -> 7 | E20: N/A — equity data unavailable | F20: N/A — EBITDA inputs unavailable | G20: =IFERROR(Financial_Metrics!C51/Financial_Metrics!C44,"") -> 0.13801757 | H20: =IFERROR(Financial_Metrics!C49/Financial_Metrics!C55,"") -> 0.24509804 | I20: Current ratio = current assets / current liabilities; coverage = EBIT / interest expense; FCF margin = FCF / revenue; OCF/debt = operating cash flow / total debt. | J20: Provisional: formula-driven, but source inputs for balance-sheet and cash-flow ratios still need reconciliation. Debt-to-Equity and Debt-to-EBITDA unavailable. | K20: =IFERROR(Financial_Metrics!C46/Financial_Metrics!C44,"") -> 0.17565872
A21: AJG | B21: 2022 | C21: =IFERROR(Financial_Metrics!D52/Financial_Metrics!D53,"") -> 1.2391304 | D21: =IFERROR(Financial_Metrics!D46/Financial_Metrics!D56,"") -> 7.0454545 | E21: N/A — equity data unavailable | F21: N/A — EBITDA inputs unavailable | G21: =IFERROR(Financial_Metrics!D51/Financial_Metrics!D44,"") -> 0.1452381 | H21: =IFERROR(Financial_Metrics!D49/Financial_Metrics!D55,"") -> 0.25925926 | I21: Current ratio = current assets / current liabilities; coverage = EBIT / interest expense; FCF margin = FCF / revenue; OCF/debt = operating cash flow / total debt. | J21: Provisional: formula-driven, but source inputs for balance-sheet and cash-flow ratios still need reconciliation. Debt-to-Equity and Debt-to-EBITDA unavailable. | K21: =IFERROR(Financial_Metrics!D46/Financial_Metrics!D44,"") -> 0.18452381
A22: AJG | B22: 2023 | C22: =IFERROR(Financial_Metrics!E52/Financial_Metrics!E53,"") -> 1.2307692 | D22: =IFERROR(Financial_Metrics!E46/Financial_Metrics!E56,"") -> 5.928 | E22: N/A — equity data unavailable | F22: N/A — EBITDA inputs unavailable | G22: =IFERROR(Financial_Metrics!E51/Financial_Metrics!E44,"") -> 0.14694202 | H22: =IFERROR(Financial_Metrics!E49/Financial_Metrics!E55,"") -> 0.27419355 | I22: Current ratio = current assets / current liabilities; coverage = EBIT / interest expense; FCF margin = FCF / revenue; OCF/debt = operating cash flow / total debt. | J22: Provisional: formula-driven, but source inputs for balance-sheet and cash-flow ratios still need reconciliation. Debt-to-Equity and Debt-to-EBITDA unavailable. | K22: =IFERROR(Financial_Metrics!E46/Financial_Metrics!E44,"") -> 0.14714059
A23: AJG | B23: 2024 | C23: =IFERROR(Financial_Metrics!F52/Financial_Metrics!F53,"") -> 1.226087 | D23: =IFERROR(Financial_Metrics!F46/Financial_Metrics!F56,"") -> 5.9212598 | E23: N/A — equity data unavailable | F23: N/A — EBITDA inputs unavailable | G23: =IFERROR(Financial_Metrics!F51/Financial_Metrics!F44,"") -> 0.12808308 | H23: =IFERROR(Financial_Metrics!F49/Financial_Metrics!F55,"") -> 0.25 | I23: Current ratio = current assets / current liabilities; coverage = EBIT / interest expense; FCF margin = FCF / revenue; OCF/debt = operating cash flow / total debt. | J23: Provisional: formula-driven, but source inputs for balance-sheet and cash-flow ratios still need reconciliation. Debt-to-Equity and Debt-to-EBITDA unavailable. | K23: =IFERROR(Financial_Metrics!F46/Financial_Metrics!F44,"") -> 0.19524016
A24: AJG | B24: 2025 | C24: =IFERROR(Financial_Metrics!G52/Financial_Metrics!G53,"") -> 1.25 | D24: =IFERROR(Financial_Metrics!G46/Financial_Metrics!G56,"") -> 3.9280125 | E24: N/A — equity data unavailable | F24: N/A — EBITDA inputs unavailable | G24: =IFERROR(Financial_Metrics!G51/Financial_Metrics!G44,"") -> 0.15062401 | H24: =IFERROR(Financial_Metrics!G49/Financial_Metrics!G55,"") -> 0.30379747 | I24: Current ratio = current assets / current liabilities; coverage = EBIT / interest expense; FCF margin = FCF / revenue; OCF/debt = operating cash flow / total debt. | J24: Provisional: formula-driven, but source inputs for balance-sheet and cash-flow ratios still need reconciliation. Debt-to-Equity and Debt-to-EBITDA unavailable. | K24: =IFERROR(Financial_Metrics!G46/Financial_Metrics!G44,"") -> 0.18003156
A25: AJG | B25: 2026_TTM | C25: =IFERROR(Financial_Metrics!H52/Financial_Metrics!H53,"") -> 1.2465753 | D25: =IFERROR(Financial_Metrics!H46/Financial_Metrics!H56,"") -> 8.6111111 | E25: N/A — equity data unavailable | F25: N/A — EBITDA inputs unavailable | G25: =IFERROR(Financial_Metrics!H51/Financial_Metrics!H44,"") -> 0.15873016 | H25: =IFERROR(Financial_Metrics!H49/Financial_Metrics!H55,"") -> 0.32758621 | I25: Current ratio = current assets / current liabilities; coverage = EBIT / interest expense; FCF margin = FCF / revenue; OCF/debt = operating cash flow / total debt. | J25: Provisional: formula-driven, but source inputs for balance-sheet and cash-flow ratios still need reconciliation. Debt-to-Equity and Debt-to-EBITDA unavailable. | K25: =IFERROR(Financial_Metrics!H46/Financial_Metrics!H44,"") -> 0.1968254
A26: BRO | B26: 2021 | C26: =IFERROR(Financial_Metrics!C66/Financial_Metrics!C67,"") -> 1.3684211 | D26: =IFERROR(Financial_Metrics!C60/Financial_Metrics!C70,"") -> 7.5 | E26: N/A — equity data unavailable | F26: N/A — EBITDA inputs unavailable | G26: =IFERROR(Financial_Metrics!C65/Financial_Metrics!C58,"") -> 0.21311475 | H26: =IFERROR(Financial_Metrics!C63/Financial_Metrics!C69,"") -> 0.25 | I26: Current ratio = current assets / current liabilities; coverage = EBIT / interest expense; FCF margin = FCF / revenue; OCF/debt = operating cash flow / total debt. | J26: Provisional: formula-driven, but source inputs for balance-sheet and cash-flow ratios still need reconciliation. Debt-to-Equity and Debt-to-EBITDA unavailable. | K26: =IFERROR(Financial_Metrics!C60/Financial_Metrics!C58,"") -> 0.24590164
A27: BRO | B27: 2022 | C27: =IFERROR(Financial_Metrics!D66/Financial_Metrics!D67,"") -> 1.3809524 | D27: =IFERROR(Financial_Metrics!D60/Financial_Metrics!D70,"") -> 8.1818182 | E27: N/A — equity data unavailable | F27: N/A — EBITDA inputs unavailable | G27: =IFERROR(Financial_Metrics!D65/Financial_Metrics!D58,"") -> 0.21714286 | H27: =IFERROR(Financial_Metrics!D63/Financial_Metrics!D69,"") -> 0.26451613 | I27: Current ratio = current assets / current liabilities; coverage = EBIT / interest expense; FCF margin = FCF / revenue; OCF/debt = operating cash flow / total debt. | J27: Provisional: formula-driven, but source inputs for balance-sheet and cash-flow ratios still need reconciliation. Debt-to-Equity and Debt-to-EBITDA unavailable. | K27: =IFERROR(Financial_Metrics!D60/Financial_Metrics!D58,"") -> 0.25714286
A28: BRO | B28: 2023 | C28: =IFERROR(Financial_Metrics!E66/Financial_Metrics!E67,"") -> 1.3913043 | D28: =IFERROR(Financial_Metrics!E60/Financial_Metrics!E70,"") -> 7.0315789 | E28: N/A — equity data unavailable | F28: N/A — EBITDA inputs unavailable | G28: =IFERROR(Financial_Metrics!E65/Financial_Metrics!E58,"") -> 0.20671835 | H28: =IFERROR(Financial_Metrics!E63/Financial_Metrics!E69,"") -> 0.27941176 | I28: Current ratio = current assets / current liabilities; coverage = EBIT / interest expense; FCF margin = FCF / revenue; OCF/debt = operating cash flow / total debt. | J28: Provisional: formula-driven, but source inputs for balance-sheet and cash-flow ratios still need reconciliation. Debt-to-Equity and Debt-to-EBITDA unavailable. | K28: =IFERROR(Financial_Metrics!E60/Financial_Metrics!E58,"") -> 0.31383603
